Workbook
Name lst_Panca_orizzontale: '_LISTE'!$D$2:$D$11
Name lst_Spinta_inclinata: '_LISTE'!$E$2:$E$9
Name lst_Pec_fly: '_LISTE'!$F$2:$F$7
Name lst_Lat_verticale: '_LISTE'!$G$2:$G$11
Name lst_Row_orizzontale: '_LISTE'!$H$2:$H$11
Name lst_Spinta_spalle: '_LISTE'!$I$2:$I$9
Name lst_Laterale: '_LISTE'!$J$2:$J$9
Name lst_Rear_delt: '_LISTE'!$K$2:$K$7
Name lst_Bicipite: '_LISTE'!$L$2:$L$13
Name lst_Tricipite: '_LISTE'!$M$2:$M$13
Name lst_Quad_squat: '_LISTE'!$N$2:$N$12
Name lst_Pressa: '_LISTE'!$O$2:$O$8
Name lst_Estensione_ginocchio: '_LISTE'!$P$2:$P$6
Name lst_Flessione_ginocchio: '_LISTE'!$Q$2:$Q$7
Name lst_Hip_hinge: '_LISTE'!$R$2:$R$14
Name lst_Polpaccio: '_LISTE'!$S$2:$S$9
Name lst_Adduttori: '_LISTE'!$T$2:$T$3
Name lst_Abduttori: '_LISTE'!$U$2:$U$3
Name lst_Addome: '_LISTE'!$V$2:$V$10

Sheet 00 COVER

Sheet 00 DASHBOARD
A1: PROGRAMMA BODYBUILDING • 16 SETTIMANE
A2: 94 kg • 1,76 m • ~10–11% BF • 4 giorni • obiettivo: ipertrofia con mantenimento della forza
A4: STRUTTURA SETTIMANALE
A5: Giorno | B5: Seduta | C5: Focus | D5: Esercizi chiave | E5: Passi target
A6: Lunedì | B6: UPPER A | C6: Petto + dorso | D6: Panca / chest press / lat / row | E6: 6–10k
A7: Martedì | B7: LOWER A | C7: Quad dominant | D7: Smith squat / pressa / extension | E7: 6–10k
A8: Mercoledì | B8: RIPOSO | C8: Recupero | D8: Camminata leggera | E8: 6–10k
A9: Giovedì | B9: UPPER B | C9: Dorso + spalle + braccia | D9: Row / lat / shoulder press / curl | E9: 6–10k
A10: Venerdì | B10: LOWER B | C10: Posterior chain | D10: RDL / pressa / leg curl / Smith squat | E10: 6–10k
A11: Sabato | B11: RIPOSO | C11: Recupero | D11: Camminata | E11: 6–10k
A12: Domenica | B12: RIPOSO | C12: Recupero | D12: Camminata | E12: 6–10k
A14: BLOCCHI DI PERIODIZZAZIONE
A15: Settimane | B15: Blocco | C15: Obiettivo | D15: RIR indicativo | E15: Volume
A16: 1–3 | B16: Accumulo 1 | C16: Calibrare e costruire | D16: 2 → 1 | E16: Base
A17: 4 | B17: Deload | C17: Recupero | D17: 3–4 | E17: -40/50%
A18: 5–7 | B18: Accumulo 2 | C18: Intensificare | D18: 2 → 1 | E18: Base +
A19: 8 | B19: Deload | C19: Recupero | D19: 3–4 | E19: -40/50%
A20: 9–11 | B20: Accumulo 3 | C20: Progressione | D20: 2 → 0/1 isolamenti | E20: Base +
A21: 12 | B21: Deload | C21: Recupero | D21: 3–4 | E21: -40/50%
A22: 13–15 | B22: Realizzazione | C22: Efficienza / performance | D22: 2 → 0/1 isolamenti | E22: Controllato
A23: 16 | B23: Deload / check | C23: Scarico e verifica | D23: 3–4 | E23: -50%
A25: REGOLE RAPIDE
A26: • Compound: di norma RIR 2→1; niente grind inutili.
A27: • Isolamenti: RIR 1 e, nelle settimane dure, ultima serie anche RIR 0 tecnico.
A28: • Doppia progressione: raggiungi il limite alto del range con il RIR richiesto → aumenta il minimo incremento.
A29: • Se perdi ≥2 reps allo stesso carico senza una spiegazione chiara → mantieni o riduci il carico.
A30: • Passi: target medio ~8.000/die; 6–10k è il range operativo. Evitare aumenti simultanei di passi e volume lower.
H31: → CONSOLE SOSTITUZIONI
A33: NAVIGAZIONE RAPIDA
A34: Settimana 1 | C34: Settimana 2 | E34: Settimana 3 | G34: Settimana 4
A35: Settimana 5 | C35: Settimana 6 | E35: Settimana 7 | G35: Settimana 8
A36: Settimana 9 | C36: Settimana 10 | E36: Settimana 11 | G36: Settimana 12
A37: Le W01–W16 partono da esercizi già utilizzati nel 2026 (es. chest press, shoulder press convergente, low row, lat machine, stacco, pressa single-leg, leg extension/curl, curl singolo al cavo). Ogni cella resta modificabile dal menu.
A40: FOCUS 16 SETTIMANE
A41: 1) Dorsali/larghezza 2) Deltoide laterale 3) Parte alta petto 4) Femorali
A42: Volume base: Petto ~12 • Dorso ~16 • Deltoidi ~13 • Quad ~14 • Femorali ~9
A43: Peso iniziale di riferimento: 94,0 kg • Passi target: 6–10k/die

Sheet 08 SOSTITUZIONI
A1: CONSOLE SOSTITUZIONI • MODIFICA REALE DEL PROGRAMMA
A2: Le settimane hanno già un esercizio predefinito. Puoi modificarlo direttamente nella colonna 'Esercizio effettivo' di ogni settimana usando il menu a tendina. Questa pagina resta come archivio/console delle sostituzioni.
A4: Settimana da | B4: Giorno | C4: Movimento | D4: Esercizio originale | E4: Nuovo esercizio | F4: Ambito | G4: Attiva | H4: Chiave | I4: Stato
A5: 1 | B5: UPPER A • PETTO + DORSO | C5: Panca orizzontale | D5: Panca piana – top set | F5: Tutte le 16 settimane | G5: NO | H5: 1|UPPER A • PETTO + DORSO|Panca orizzontale|Panca piana – top set | I5: =IF(G5<>"SI","Inattiva",IF(E5="","Manca nuovo esercizio","ATTIVA"))
A6: 1 | B6: UPPER A • PETTO + DORSO | C6: Panca orizzontale | D6: Panca piana – back-off | F6: Tutte le 16 settimane | G6: NO | H6: 1|UPPER A • PETTO + DORSO|Panca orizzontale|Panca piana – back-off | I6: =IF(G6<>"SI","Inattiva",IF(E6="","Manca nuovo esercizio","ATTIVA"))
A7: 1 | B7: UPPER A • PETTO + DORSO | C7: Spinta inclinata | D7: Chest press inclinata | F7: Tutte le 16 settimane | G7: NO | H7: 1|UPPER A • PETTO + DORSO|Spinta inclinata|Chest press inclinata | I7: =IF(G7<>"SI","Inattiva",IF(E7="","Manca nuovo esercizio","ATTIVA"))
A8: 1 | B8: UPPER A • PETTO + DORSO | C8: Lat verticale | D8: Lat machine | F8: Tutte le 16 settimane | G8: NO | H8: 1|UPPER A • PETTO + DORSO|Lat verticale|Lat machine | I8: =IF(G8<>"SI","Inattiva",IF(E8="","Manca nuovo esercizio","ATTIVA"))
A9: 1 | B9: UPPER A • PETTO + DORSO | C9: Row orizzontale | D9: Low row 1 braccio | F9: Tutte le 16 settimane | G9: NO | H9: 1|UPPER A • PETTO + DORSO|Row orizzontale|Low row 1 braccio | I9: =IF(G9<>"SI","Inattiva",IF(E9="","Manca nuovo esercizio","ATTIVA"))
A10: 1 | B10: UPPER A • PETTO + DORSO | C10: Pec fly | D10: Pec fly | F10: Tutte le 16 settimane | G10: NO | H10: 1|UPPER A • PETTO + DORSO|Pec fly|Pec fly | I10: =IF(G10<>"SI","Inattiva",IF(E10="","Manca nuovo esercizio","ATTIVA"))
A11: 1 | B11: UPPER A • PETTO + DORSO | C11: Laterale | D11: Alzate laterali cavi | F11: Tutte le 16 settimane | G11: NO | H11: 1|UPPER A • PETTO + DORSO|Laterale|Alzate laterali cavi | I11: =IF(G11<>"SI","Inattiva",IF(E11="","Manca nuovo esercizio","ATTIVA"))
A12: 1 | B12: UPPER A • PETTO + DORSO | C12: Tricipite | D12: Pushdown cavo | F12: Tutte le 16 settimane | G12: NO | H12: 1|UPPER A • PETTO + DORSO|Tricipite|Pushdown cavo | I12: =IF(G12<>"SI","Inattiva",IF(E12="","Manca nuovo esercizio","ATTIVA"))
A13: 1 | B13: LOWER A • QUAD DOMINANT | C13: Quad squat | D13: Smith squat quad-biased | F13: Tutte le 16 settimane | G13: NO | H13: 1|LOWER A • QUAD DOMINANT|Quad squat|Smith squat quad-biased | I13: =IF(G13<>"SI","Inattiva",IF(E13="","Manca nuovo esercizio","ATTIVA"))
A14: 1 | B14: LOWER A • QUAD DOMINANT | C14: Pressa | D14: Leg press singola | F14: Tutte le 16 settimane | G14: NO | H14: 1|LOWER A • QUAD DOMINANT|Pressa|Leg press singola | I14: =IF(G14<>"SI","Inattiva",IF(E14="","Manca nuovo esercizio","ATTIVA"))
A15: 1 | B15: LOWER A • QUAD DOMINANT | C15: Estensione ginocchio | D15: Leg extension | F15: Tutte le 16 settimane | G15: NO | H15: 1|LOWER A • QUAD DOMINANT|Estensione ginocchio|Leg extension | I15: =IF(G15<>"SI","Inattiva",IF(E15="","Manca nuovo esercizio","ATTIVA"))
A16: 1 | B16: LOWER A • QUAD DOMINANT | C16: Flessione ginocchio | D16: Leg curl singola | F16: Tutte le 16 settimane | G16: NO | H16: 1|LOWER A • QUAD DOMINANT|Flessione ginocchio|Leg curl singola | I16: =IF(G16<>"SI","Inattiva",IF(E16="","Manca nuovo esercizio","ATTIVA"))
... A36: 1 | B36: LOWER B • POSTERIOR CHAIN + QUAD | C36: Addome | D36: Cable crunch | F36: Tutte le 16 settimane | G36: NO | H36: 1|LOWER B • POSTERIOR CHAIN + QUAD|Addome|Cable crunch | I36: =IF(G36<>"SI","Inattiva",IF(E36="","Manca nuovo esercizio","ATTIVA"))
A38: FUNZIONAMENTO: seleziona una sostituzione, scegli l'ambito e metti ATTIVA = SI. Non serve spuntare altro: le schede W01–W16 leggono questa console. 'Solo dalla settimana scelta' vale dalla settimana indicata in poi solo per quella riga; 'Da questa in poi' vale per tutte le settimane successive; 'Tutte' per tutte le 16.

Sheet 01 SETUP
A1: SETUP & ISTRUZIONI
A2: Come usare il file in palestra
H3: ← Dashboard
A4: PARAMETRI
A5: Peso attuale | B5: 94 kg
A6: Altezza | B6: 1,76 m
A7: BF stimato | B7: ~10–11%
A8: Frequenza | B8: 4 giorni/settimana
A9: Split | B9: Upper / Lower / Upper / Lower
A10: Passi target | B10: media ~8.000/die; range 6–10k
A11: Obiettivo | B11: Ipertrofia + mantenimento della forza
A14: COME COMPILARE LE SCHEDE SETTIMANALI
A15: • Usa la colonna Carico pianificato come punto di partenza, non come obbligo.
A16: • Dopo ogni esercizio registra Carico reale, Reps reali e RIR reale.
A17: • Per esercizi unilaterali, indica il carico per lato se applicabile.
A18: • Se il primo set è molto più duro/leggero del previsto, autoregola i successivi.
A19: • Il volume e la progressione vanno interpretati insieme a performance, recupero e media passi.
A21: REGOLE OPERATIVE DEL PROGRAMMA
A22: Regole di progressione, autoregolazione e gestione della fatica — integrate qui per avere tutto il necessario in una sola pagina.
A23: REGOLA | B23: APPLICAZIONE
A24: Doppia progressione | B24: Mantieni il carico finché non raggiungi il limite alto del range in tutte le serie con il RIR richiesto. Poi aumenta il minimo incremento disponibile.
A25: Top set + back-off | B25: Panca e low row: un set principale controllato seguito da back-off. Il back-off segue il carico reale del top set, non il carico pianificato.
A26: RIR | B26: W1–2 2 RIR; W3 1 RIR; W4 3–4 RIR; W5 2; W6–7 1; W8 3–4; W9–10 2→1; W11 0–1 solo su isolamenti; W12 3–4; W13–14 2→1; W15 0–1 su isolamenti; W16 3–4.
A27: Deload | B27: W4/W8/W12/W16: circa 50% delle serie. Mantieni pattern, riduci fatica, niente cedimento.
A28: Step target | B28: Media settimanale ~8.000/die; range operativo 6.000–10.000. Se passi aumentano oltre 10k per più settimane, non aumentare contemporaneamente volume gambe.
A29: Aggiustamento fatica | B29: Se per 2 sedute consecutive perdi ≥2 reps allo stesso carico o RPE sale di ≥1 a parità di lavoro, mantieni/riduci carico o una serie.
A30: Aggiustamento volume | B30: Aggiungi 1 serie a un muscolo solo se performance, recupero e sintomi sono buoni per almeno 2 settimane.
A31: Forza | B31: Mantieni panca/squat/RDL con esposizione sufficiente per preservare skill e forza, ma non trasformare il programma in PL.
A32: Macchine | B32: I kg sono specifici della macchina. Non confrontare 60 kg di una chest press con 60 kg di un’altra.
A34: NOTA DATABASE ESERCIZI • Il database completo resta attivo dietro i menu a tendina: le sostituzioni si effettuano direttamente nelle settimane, senza bisogno di una pagina separata.

Sheet 02 BASELINE
A1: BASELINE 2026
A2: Riferimenti reali usati per impostare i carichi iniziali
G3: ← Dashboard
A4: Esercizio | B4: Ultimo riferimento 2026 | C4: Miglior riferimento utile | D4: Range recente | E4: Baseline proposta W1 | F4: RIR target W1 | G4: Note
A5: Panca piana / strength anchor | B5: 140 x 3/2 (22 ago) | C5: 160 x 1 confermato; 165 tentato senza successo | D5: 1–5 | E5: 130 kg top set 5–7; back-off 120 kg 3x7–9 | F5: 2 | G5: Usata come mantenimento forza, non come focus ipertrofico principale.
A6: Chest press inclinata | B6: 60 x 9/8 a cedimento (18 ago) | C6: 60 x 9 | D6: 8–12 | E6: 55 kg | F6: 2 | G6: Nuova macchina: calibrare la prima seduta.
A7: Panca inclinata manubri | B7: 31 x 10; 34 a cedimento (22 ago) | C7: 41,5 x 10 storico | D7: 8–12 | E7: 31 kg/DB | F7: 2 | G7: Preferire tecnica stabile; 34 kg è attualmente vicino al limite.
A8: Pec fly | B8: 90 x 10/10 (15–22 ago) | C8: 90 x 10 | D8: 10–15 | E8: 80 kg | F8: 2 | G8: Macchina: mantenere ROM e picco di contrazione.
A9: Lat machine | B9: 70 x 9 tecnico; 65 x10/10/9 | C9: 95 x 10 storico | D9: 8–12 | E9: 67,5 kg | F9: 2 | G9: Carico recente più rappresentativo.
A10: Low row 1 braccio | B10: 70 x 10/10 (ripetuto luglio-agosto) | C10: 70 x 10/10 | D10: 8–12 | E10: 65 kg | F10: 2 | G10: Unilaterale; 65 è la base di lavoro, 70 è target alto.
A11: Pulley basso | B11: 90 x 12/12/12 (ripetuto) | C11: 125 x12 storico | D11: 10–15 | E11: 90 kg | F11: 2 | G11: Ottima baseline recente.
A12: Shoulder press convergente | B12: 60 x 8 ripetuto | C12: 80 x4 storico | D12: 6–10 | E12: 55 kg | F12: 2 | G12: Non inseguire il 4RM: priorità deltoidi e stabilità.
A13: Alzate laterali manubri | B13: 32,5 x 10 | C13: 32,5 x10 | D13: 10–20 | E13: 26,5 kg | F13: 2 | G13: Usare 32,5 come top della progressione, non come base.
A14: Alzate laterali cavi | B14: 18 x15/15/15 | C14: 18 x15 | D14: 12–20 | E14: 18 kg | F14: 2 | G14: Baseline molto stabile.
A15: Rear delt machine | B15: 60 x12/12/12/12 | C15: 90 x12 storico singola | D15: 12–20 | E15: 60 kg | F15: 2 | G15: Baseline recente e ripetibile.
A16: Curl singolo cavo | B16: 27 x12; 31 x12/12 ripetuto | C16: 31 x12/12 | D16: 8–12 | E16: 31 kg | F16: 2 | G16: Esercizio principale bicipiti; preferenza utente.
... A24: Abductor | B24: ~80–82,5 x24 storico | C24: 82,5 x24 | D24: 12–20 | E24: 80 kg | F24: 2 | G24: Da calibrare se macchina/setting cambiati.

Sheet 03 EVIDENCE
A1: EVIDENCE & RAZIONALE
A2: Sintesi delle fonti usate per le principali scelte di programmazione
D3: ← Dashboard
A4: Tema | B4: Evidenza recente | C4: Come viene applicata nel programma | D4: Fonte
A5: Prossimità al cedimento | B5: La meta-regressione 2024 indica che l’ipertrofia tende ad aumentare quando le serie terminano più vicino al cedimento, ma l’effetto preciso/RIR ottimale resta incerto; una revisione precedente non mostra superiorità necessaria del cedimento momentaneo. | C5: Compound principalmente RIR 2→1; isolamenti/machine più vicini al cedimento nelle settimane dure. | D5: Robinson et al. 2024; Refalo et al. 2023
A6: Volume settimanale | B6: Il volume mostra una relazione dose-risposta generale, ma un RCT 2025 in uomini allenati ha trovato crescita anche mantenendo il volume precedente e nessun vantaggio chiaro aumentando del 30–60%. | C6: Partenza con volume moderato; aumenti graduali e non automatici; deload regolari. | D6: Schoenfeld et al. 2016; Barsuhn et al. 2025
A7: Frequenza | B7: Quando il volume è equato, la frequenza da sola non sembra determinare grandi differenze di ipertrofia. | C7: Upper/Lower 4 giorni distribuisce ogni grande distretto su 2 esposizioni/settimana. | D7: Schoenfeld et al. 2019; Ramos-Campo et al. 2024
A8: Carico | B8: Meta-analisi: con volume-equated, l’ipertrofia può essere simile su un ampio range di carichi; i carichi alti favoriscono maggiormente la forza. | C8: Range misti: 6–10 sui compound e 8–20 sugli accessori, senza legare l’ipertrofia a un singolo range. | D8: Carvalho et al. 2022; NMA 2023
A9: Recupero tra serie | B9: La revisione Bayesian 2024 suggerisce un piccolo vantaggio per >60 s e nessuna differenza apprezzabile oltre ~90 s nei confronti diretti; per mantenere performance si possono usare recuperi lunghi. | C9: 2,5–4 min compound; 2–3 min machine compound; 60–120 s isolamenti. | D9: Singer et al. 2024
A10: ROM | B10: La meta-analisi sul ROM trova un piccolo/triviale vantaggio complessivo del full ROM rispetto al partial ROM, con variabilità tra distretti. | C10: ROM completo e ripetibile come standard; niente ROM forzato se altera tecnica o comfort. | D10: Partial vs Full ROM systematic review/meta-analysis
A11: Periodizzazione | B11: La meta-analisi 2022 trova vantaggi della periodizzazione per la forza ma differenze piccole/non significative per ipertrofia quando il volume è equato. | C11: 4 blocchi: accumulo → deload → intensificazione, senza complicare inutilmente la selezione esercizi. | D11: Williams et al. 2022
A12: Passi / attività | B12: Il numero di passi aumenta il dispendio e la fatica periferica; non esiste una soglia universale specifica per l’ipertrofia in soggetti allenati. | C12: Target medio ~8k/die; mantenere stabile la media durante il mesociclo e non usare i passi come cardio punitivo. | D12: Principio pratico di gestione del carico; monitorare risposta individuale
A14: RICERCA ESTERNA — PRINCIPI USATI PER V11
A15: • Volume: la letteratura supporta una relazione dose-risposta positiva, ma per un atleta avanzato il criterio pratico è trovare il massimo volume recuperabile/produttivo, non inseguire automaticamente più serie.
A16: • Frequenza: a volume equivalente la frequenza non mostra un vantaggio importante sull'ipertrofia; qui la frequenza 2x serve soprattutto a distribuire qualità e fatica.
A17: • RIR: le serie vicine al cedimento possono favorire l'ipertrofia, ma il cedimento momentaneo non è necessario; i multiarticolari restano prevalentemente a RIR 2→1.
A18: • Periodizzazione: non è stata usata per 'magia ipertrofica', ma per distribuire accumulo, intensificazione e deload lungo 16 settimane.
A20: Volume — PubMed | B20: https://pubmed.ncbi.nlm.nih.gov/27433992/
A21: RIR — meta-regressione 2024 | B21: https://pubmed.ncbi.nlm.nih.gov/38970765/
A22: Frequenza — meta-analisi | B22: https://pubmed.ncbi.nlm.nih.gov/30558493/
A23: Periodizzazione — meta-analisi | B23: https://pubmed.ncbi.nlm.nih.gov/35044672/

Sheet 04 PROGRESSO
A1: GIAMMARIA SYSTEM • PERFORMANCE CENTER
A2: Performance = Σ[carico reale × (reps reali + RIR reale)]. RIR 0 = cedimento; le percentuali confrontano la stessa prestazione con la settimana precedente.
A4: WEEK | B4: SERIE REGISTRATE | C4: VOLUME REALE (kg) | D4: Δ VOLUME | E4: INTENSITÀ MEDIA* | F4: Δ INTENSITÀ | G4: PESO (kg) | H4: PERFORMANCE WEEK
A5: 1 | B5: =SUM(COUNT('W01'!$H$9:$H$31),COUNT('W01'!$H$35:$H$55),COUNT('W01'!$H$59:$H$85),COUNT('W01'!$H$89:$H$109)) | C5: =(SUMPRODUCT(IFERROR('W01'!$H$9:$H$31*'W01'!$I$9:$I$31,0))+SUMPRODUCT(IFERROR('W01'!$H$35:$H$55*'W01'!$I$35:$I$55,0))+SUMPRODUCT(IFERROR('W01'!$H$59:$H$85*'W01'!$I$59:$I$85,0))+SUMPRODUCT(IFERROR('W01'!$H$89:$H$109*'W01'!$I$89:$I$109,0))) | D5: ="" | E5: =IFERROR((SUMPRODUCT(IFERROR('W01'!$H$9:$H$31*(1+'W01'!$I$9:$I$31/30),0))+SUMPRODUCT(IFERROR('W01'!$H$35:$H$55*(1+'W01'!$I$35:$I$55/30),0))+SUMPRODUCT(IFERROR('W01'!$H$59:$H$85*(1+'W01'!$I$59:$I$85/30),0))+SUMPRODUCT(IFERROR('W01'!$H$89:$H$109*(1+'W01'!$I$89:$I$109/30),0)))/B5,"") | F5: ="" | G5: ='W01'!E4 | H5: =""
A6: 2 | B6: =SUM(COUNT('W02'!$H$9:$H$31),COUNT('W02'!$H$35:$H$55),COUNT('W02'!$H$59:$H$85),COUNT('W02'!$H$89:$H$109)) | C6: =(SUMPRODUCT(IFERROR('W02'!$H$9:$H$31*'W02'!$I$9:$I$31,0))+SUMPRODUCT(IFERROR('W02'!$H$35:$H$55*'W02'!$I$35:$I$55,0))+SUMPRODUCT(IFERROR('W02'!$H$59:$H$85*'W02'!$I$59:$I$85,0))+SUMPRODUCT(IFERROR('W02'!$H$89:$H$109*'W02'!$I$89:$I$109,0))) | D6: =IFERROR(C6/(SUMPRODUCT(IFERROR('W01'!$H$9:$H$31*'W01'!$I$9:$I$31,0))+SUMPRODUCT(IFERROR('W01'!$H$35:$H$55*'W01'!$I$35:$I$55,0))+SUMPRODUCT(IFERROR('W01'!$H$59:$H$85*'W01'!$I$59:$I$85,0))+SUMPRODUCT(IFERROR('W01'!$H$89:$H$109*'W01'!$I$89:$I$109,0)))-1,"") | E6: =IFERROR((SUMPRODUCT(IFERROR('W02'!$H$9:$H$31*(1+'W02'!$I$9:$I$31/30),0))+SUMPRODUCT(IFERROR('W02'!$H$35:$H$55*(1+'W02'!$I$35:$I$55/30),0))+SUMPRODUCT(IFERROR('W02'!$H$59:$H$85*(1+'W02'!$I$59:$I$85/30),0))+SUMPRODUCT(IFERROR('W02'!$H$89:$H$109*(1+'W02'!$I$89:$I$109/30),0)))/B6,"") | F6: =IFERROR(E6/((SUMPRODUCT(IFERROR('W01'!$H$9:$H$31*(1+'W01'!$I$9:$I$31/30),0))+SUMPRODUCT(IFERROR('W01'!$H$35:$H$55*(1+'W01'!$I$35:$I$55/30),0))+SUMPRODUCT(IFERROR('W01'!$H$59:$H$85*(1+'W01'!$I$59:$I$85/30),0))+SUMPRODUCT(IFERROR('W01'!$H$89:$H$109*(1+'W01'!$I$89:$I$109/30),0)))/B5)-1,"") | G6: ='W02'!E4 | H6: =IFERROR((SUMPRODUCT(IFERROR('W02'!$H$9:$H$31*('W02'!$I$9:$I$31+'W02'!$J$9:$J$31),0))+SUMPRODUCT(IFERROR('W02'!$H$35:$H$55*('W02'!$I$35:$I$55+'W02'!$J$35:$J$55),0))+SUMPRODUCT(IFERROR('W02'!$H$59:$H$85*('W02'!$I$59:$I$85+'W02'!$J$59:$J$85),0))+SUMPRODUCT(IFERROR('W02'!$H$89:$H$109*('W02'!$I$89:$I$109+'W02'!$J$89:$J$109),0)))/(SUMPRODUCT(IFERROR('W01'!$H$9:$H$31*('W01'!$I$9:$I$31+'W01'!$J$9:$J$31),0))+SUMPRODUCT(IFERROR('W01'!$H$35:$H$55*('W01'!$I$35:$I$55+'W01'!$J$35:$J$55),0))+SUMPRODUCT(IFERROR('W01'!$H$59:$H$85*('W01'!$I$59:$I$85+'W01'!$J$59:$J$85),0))+SUMPRODUCT(IFERROR('W01'!$H$89:$H$109*('W01'!$I$89:$I$109+'W01'!$J$89:$J$109),0)))-1,"")
A7: 3 | B7: =SUM(COUNT('W03'!$H$9:$H$31),COUNT('W03'!$H$35:$H$55),COUNT('W03'!$H$59:$H$85),COUNT('W03'!$H$89:$H$109)) | C7: =(SUMPRODUCT(IFERROR('W03'!$H$9:$H$31*'W03'!$I$9:$I$31,0))+SUMPRODUCT(IFERROR('W03'!$H$35:$H$55*'W03'!$I$35:$I$55,0))+SUMPRODUCT(IFERROR('W03'!$H$59:$H$85*'W03'!$I$59:$I$85,0))+SUMPRODUCT(IFERROR('W03'!$H$89:$H$109*'W03'!$I$89:$I$109,0))) | D7: =IFERROR(C7/(SUMPRODUCT(IFERROR('W02'!$H$9:$H$31*'W02'!$I$9:$I$31,0))+SUMPRODUCT(IFERROR('W02'!$H$35:$H$55*'W02'!$I$35:$I$55,0))+SUMPRODUCT(IFERROR('W02'!$H$59:$H$85*'W02'!$I$59:$I$85,0))+SUMPRODUCT(IFERROR('W02'!$H$89:$H$109*'W02'!$I$89:$I$109,0)))-1,"") | E7: =IFERROR((SUMPRODUCT(IFERROR('W03'!$H$9:$H$31*(1+'W03'!$I$9:$I$31/30),0))+SUMPRODUCT(IFERROR('W03'!$H$35:$H$55*(1+'W03'!$I$35:$I$55/30),0))+SUMPRODUCT(IFERROR('W03'!$H$59:$H$85*(1+'W03'!$I$59:$I$85/30),0))+SUMPRODUCT(IFERROR('W03'!$H$89:$H$109*(1+'W03'!$I$89:$I$109/30),0)))/B7,"") | F7: =IFERROR(E7/((SUMPRODUCT(IFERROR('W02'!$H$9:$H$31*(1+'W02'!$I$9:$I$31/30),0))+SUMPRODUCT(IFERROR('W02'!$H$35:$H$55*(1+'W02'!$I$35:$I$55/30),0))+SUMPRODUCT(IFERROR('W02'!$H$59:$H$85*(1+'W02'!$I$59:$I$85/30),0))+SUMPRODUCT(IFERROR('W02'!$H$89:$H$109*(1+'W02'!$I$89:$I$109/30),0)))/B6)-1,"") | G7: ='W03'!E4 | H7: =IFERROR((SUMPRODUCT(IFERROR('W03'!$H$9:$H$31*('W03'!$I$9:$I$31+'W03'!$J$9:$J$31),0))+SUMPRODUCT(IFERROR('W03'!$H$35:$H$55*('W03'!$I$35:$I$55+'W03'!$J$35:$J$55),0))+SUMPRODUCT(IFERROR('W03'!$H$59:$H$85*('W03'!$I$59:$I$85+'W03'!$J$59:$J$85),0))+SUMPRODUCT(IFERROR('W03'!$H$89:$H$109*('W03'!$I$89:$I$109+'W03'!$J$89:$J$109),0)))/(SUMPRODUCT(IFERROR('W02'!$H$9:$H$31*('W02'!$I$9:$I$31+'W02'!$J$9:$J$31),0))+SUMPRODUCT(IFERROR('W02'!$H$35:$H$55*('W02'!$I$35:$I$55+'W02'!$J$35:$J$55),0))+SUMPRODUCT(IFERROR('W02'!$H$59:$H$85*('W02'!$I$59:$I$85+'W02'!$J$59:$J$85),0))+SUMPRODUCT(IFERROR('W02'!$H$89:$H$109*('W02'!$I$89:$I$109+'W02'!$J$89:$J$109),0)))-1,"")
A8: 4 | B8: =SUM(COUNT('W04'!$H$9:$H$31),COUNT('W04'!$H$35:$H$55),COUNT('W04'!$H$59:$H$85),COUNT('W04'!$H$89:$H$109)) | C8: =(SUMPRODUCT(IFERROR('W04'!$H$9:$H$31*'W04'!$I$9:$I$31,0))+SUMPRODUCT(IFERROR('W04'!$H$35:$H$55*'W04'!$I$35:$I$55,0))+SUMPRODUCT(IFERROR('W04'!$H$59:$H$85*'W04'!$I$59:$I$85,0))+SUMPRODUCT(IFERROR('W04'!$H$89:$H$109*'W04'!$I$89:$I$109,0))) | D8: =IFERROR(C8/(SUMPRODUCT(IFERROR('W03'!$H$9:$H$31*'W03'!$I$9:$I$31,0))+SUMPRODUCT(IFERROR('W03'!$H$35:$H$55*'W03'!$I$35:$I$55,0))+SUMPRODUCT(IFERROR('W03'!$H$59:$H$85*'W03'!$I$59:$I$85,0))+SUMPRODUCT(IFERROR('W03'!$H$89:$H$109*'W03'!$I$89:$I$109,0)))-1,"") | E8: =IFERROR((SUMPRODUCT(IFERROR('W04'!$H$9:$H$31*(1+'W04'!$I$9:$I$31/30),0))+SUMPRODUCT(IFERROR('W04'!$H$35:$H$55*(1+'W04'!$I$35:$I$55/30),0))+SUMPRODUCT(IFERROR('W04'!$H$59:$H$85*(1+'W04'!$I$59:$I$85/30),0))+SUMPRODUCT(IFERROR('W04'!$H$89:$H$109*(1+'W04'!$I$89:$I$109/30),0)))/B8,"") | F8: =IFERROR(E8/((SUMPRODUCT(IFERROR('W03'!$H$9:$H$31*(1+'W03'!$I$9:$I$31/30),0))+SUMPRODUCT(IFERROR('W03'!$H$35:$H$55*(1+'W03'!$I$35:$I$55/30),0))+SUMPRODUCT(IFERROR('W03'!$H$59:$H$85*(1+'W03'!$I$59:$I$85/30),0))+SUMPRODUCT(IFERROR('W03'!$H$89:$H$109*(1+'W03'!$I$89:$I$109/30),0)))/B7)-1,"") | G8: ='W04'!E4 | H8: =IFERROR((SUMPRODUCT(IFERROR('W04'!$H$9:$H$31*('W04'!$I$9:$I$31+'W04'!$J$9:$J$31),0))+SUMPRODUCT(IFERROR('W04'!$H$35:$H$55*('W04'!$I$35:$I$55+'W04'!$J$35:$J$55),0))+SUMPRODUCT(IFERROR('W04'!$H$59:$H$85*('W04'!$I$59:$I$85+'W04'!$J$59:$J$85),0))+SUMPRODUCT(IFERROR('W04'!$H$89:$H$109*('W04'!$I$89:$I$109+'W04'!$J$89:$J$109),0)))/(SUMPRODUCT(IFERROR('W03'!$H$9:$H$31*('W03'!$I$9:$I$31+'W03'!$J$9:$J$31),0))+SUMPRODUCT(IFERROR('W03'!$H$35:$H$55*('W03'!$I$35:$I$55+'W03'!$J$35:$J$55),0))+SUMPRODUCT(IFERROR('W03'!$H$59:$H$85*('W03'!$I$59:$I$85+'W03'!$J$59:$J$85),0))+SUMPRODUCT(IFERROR('W03'!$H$89:$H$109*('W03'!$I$89:$I$109+'W03'!$J$89:$J$109),0)))-1,"")
A9: 5 | B9: =SUM(COUNT('W05'!$H$9:$H$31),COUNT('W05'!$H$35:$H$55),COUNT('W05'!$H$59:$H$85),COUNT('W05'!$H$89:$H$109)) | C9: =(SUMPRODUCT(IFERROR('W05'!$H$9:$H$31*'W05'!$I$9:$I$31,0))+SUMPRODUCT(IFERROR('W05'!$H$35:$H$55*'W05'!$I$35:$I$55,0))+SUMPRODUCT(IFERROR('W05'!$H$59:$H$85*'W05'!$I$59:$I$85,0))+SUMPRODUCT(IFERROR('W05'!$H$89:$H$109*'W05'!$I$89:$I$109,0))) | D9: =IFERROR(C9/(SUMPRODUCT(IFERROR('W04'!$H$9:$H$31*'W04'!$I$9:$I$31,0))+SUMPRODUCT(IFERROR('W04'!$H$35:$H$55*'W04'!$I$35:$I$55,0))+SUMPRODUCT(IFERROR('W04'!$H$59:$H$85*'W04'!$I$59:$I$85,0))+SUMPRODUCT(IFERROR('W04'!$H$89:$H$109*'W04'!$I$89:$I$109,0)))-1,"") | E9: =IFERROR((SUMPRODUCT(IFERROR('W05'!$H$9:$H$31*(1+'W05'!$I$9:$I$31/30),0))+SUMPRODUCT(IFERROR('W05'!$H$35:$H$55*(1+'W05'!$I$35:$I$55/30),0))+SUMPRODUCT(IFERROR('W05'!$H$59:$H$85*(1+'W05'!$I$59:$I$85/30),0))+SUMPRODUCT(IFERROR('W05'!$H$89:$H$109*(1+'W05'!$I$89:$I$109/30),0)))/B9,"") | F9: =IFERROR(E9/((SUMPRODUCT(IFERROR('W04'!$H$9:$H$31*(1+'W04'!$I$9:$I$31/30),0))+SUMPRODUCT(IFERROR('W04'!$H$35:$H$55*(1+'W04'!$I$35:$I$55/30),0))+SUMPRODUCT(IFERROR('W04'!$H$59:$H$85*(1+'W04'!$I$59:$I$85/30),0))+SUMPRODUCT(IFERROR('W04'!$H$89:$H$109*(1+'W04'!$I$89:$I$109/30),0)))/B8)-1,"") | G9: ='W05'!E4 | H9: =IFERROR((SUMPRODUCT(IFERROR('W05'!$H$9:$H$31*('W05'!$I$9:$I$31+'W05'!$J$9:$J$31),0))+SUMPRODUCT(IFERROR('W05'!$H$35:$H$55*('W05'!$I$35:$I$55+'W05'!$J$35:$J$55),0))+SUMPRODUCT(IFERROR('W05'!$H$59:$H$85*('W05'!$I$59:$I$85+'W05'!$J$59:$J$85),0))+SUMPRODUCT(IFERROR('W05'!$H$89:$H$109*('W05'!$I$89:$I$109+'W05'!$J$89:$J$109),0)))/(SUMPRODUCT(IFERROR('W04'!$H$9:$H$31*('W04'!$I$9:$I$31+'W04'!$J$9:$J$31),0))+SUMPRODUCT(IFERROR('W04'!$H$35:$H$55*('W04'!$I$35:$I$55+'W04'!$J$35:$J$55),0))+SUMPRODUCT(IFERROR('W04'!$H$59:$H$85*('W04'!$I$59:$I$85+'W04'!$J$59:$J$85),0))+SUMPRODUCT(IFERROR('W04'!$H$89:$H$109*('W04'!$I$89:$I$109+'W04'!$J$89:$J$109),0)))-1,"")
A10: 6 | B10: =SUM(COUNT('W06'!$H$9:$H$31),COUNT('W06'!$H$35:$H$55),COUNT('W06'!$H$59:$H$85),COUNT('W06'!$H$89:$H$109)) | C10: =(SUMPRODUCT(IFERROR('W06'!$H$9:$H$31*'W06'!$I$9:$I$31,0))+SUMPRODUCT(IFERROR('W06'!$H$35:$H$55*'W06'!$I$35:$I$55,0))+SUMPRODUCT(IFERROR('W06'!$H$59:$H$85*'W06'!$I$59:$I$85,0))+SUMPRODUCT(IFERROR('W06'!$H$89:$H$109*'W06'!$I$89:$I$109,0))) | D10: =IFERROR(C10/(SUMPRODUCT(IFERROR('W05'!$H$9:$H$31*'W05'!$I$9:$I$31,0))+SUMPRODUCT(IFERROR('W05'!$H$35:$H$55*'W05'!$I$35:$I$55,0))+SUMPRODUCT(IFERROR('W05'!$H$59:$H$85*'W05'!$I$59:$I$85,0))+SUMPRODUCT(IFERROR('W05'!$H$89:$H$109*'W05'!$I$89:$I$109,0)))-1,"") | E10: =IFERROR((SUMPRODUCT(IFERROR('W06'!$H$9:$H$31*(1+'W06'!$I$9:$I$31/30),0))+SUMPRODUCT(IFERROR('W06'!$H$35:$H$55*(1+'W06'!$I$35:$I$55/30),0))+SUMPRODUCT(IFERROR('W06'!$H$59:$H$85*(1+'W06'!$I$59:$I$85/30),0))+SUMPRODUCT(IFERROR('W06'!$H$89:$H$109*(1+'W06'!$I$89:$I$109/30),0)))/B10,"") | F10: =IFERROR(E10/((SUMPRODUCT(IFERROR('W05'!$H$9:$H$31*(1+'W05'!$I$9:$I$31/30),0))+SUMPRODUCT(IFERROR('W05'!$H$35:$H$55*(1+'W05'!$I$35:$I$55/30),0))+SUMPRODUCT(IFERROR('W05'!$H$59:$H$85*(1+'W05'!$I$59:$I$85/30),0))+SUMPRODUCT(IFERROR('W05'!$H$89:$H$109*(1+'W05'!$I$89:$I$109/30),0)))/B9)-1,"") | G10: ='W06'!E4 | H10: =IFERROR((SUMPRODUCT(IFERROR('W06'!$H$9:$H$31*('W06'!$I$9:$I$31+'W06'!$J$9:$J$31),0))+SUMPRODUCT(IFERROR('W06'!$H$35:$H$55*('W06'!$I$35:$I$55+'W06'!$J$35:$J$55),0))+SUMPRODUCT(IFERROR('W06'!$H$59:$H$85*('W06'!$I$59:$I$85+'W06'!$J$59:$J$85),0))+SUMPRODUCT(IFERROR('W06'!$H$89:$H$109*('W06'!$I$89:$I$109+'W06'!$J$89:$J$109),0)))/(SUMPRODUCT(IFERROR('W05'!$H$9:$H$31*('W05'!$I$9:$I$31+'W05'!$J$9:$J$31),0))+SUMPRODUCT(IFERROR('W05'!$H$35:$H$55*('W05'!$I$35:$I$55+'W05'!$J$35:$J$55),0))+SUMPRODUCT(IFERROR('W05'!$H$59:$H$85*('W05'!$I$59:$I$85+'W05'!$J$59:$J$85),0))+SUMPRODUCT(IFERROR('W05'!$H$89:$H$109*('W05'!$I$89:$I$109+'W05'!$J$89:$J$109),0)))-1,"")
A11: 7 | B11: =SUM(COUNT('W07'!$H$9:$H$31),COUNT('W07'!$H$35:$H$55),COUNT('W07'!$H$59:$H$85),COUNT('W07'!$H$89:$H$109)) | C11: =(SUMPRODUCT(IFERROR('W07'!$H$9:$H$31*'W07'!$I$9:$I$31,0))+SUMPRODUCT(IFERROR('W07'!$H$35:$H$55*'W07'!$I$35:$I$55,0))+SUMPRODUCT(IFERROR('W07'!$H$59:$H$85*'W07'!$I$59:$I$85,0))+SUMPRODUCT(IFERROR('W07'!$H$89:$H$109*'W07'!$I$89:$I$109,0))) | D11: =IFERROR(C11/(SUMPRODUCT(IFERROR('W06'!$H$9:$H$31*'W06'!$I$9:$I$31,0))+SUMPRODUCT(IFERROR('W06'!$H$35:$H$55*'W06'!$I$35:$I$55,0))+SUMPRODUCT(IFERROR('W06'!$H$59:$H$85*'W06'!$I$59:$I$85,0))+SUMPRODUCT(IFERROR('W06'!$H$89:$H$109*'W06'!$I$89:$I$109,0)))-1,"") | E11: =IFERROR((SUMPRODUCT(IFERROR('W07'!$H$9:$H$31*(1+'W07'!$I$9:$I$31/30),0))+SUMPRODUCT(IFERROR('W07'!$H$35:$H$55*(1+'W07'!$I$35:$I$55/30),0))+SUMPRODUCT(IFERROR('W07'!$H$59:$H$85*(1+'W07'!$I$59:$I$85/30),0))+SUMPRODUCT(IFERROR('W07'!$H$89:$H$109*(1+'W07'!$I$89:$I$109/30),0)))/B11,"") | F11: =IFERROR(E11/((SUMPRODUCT(IFERROR('W06'!$H$9:$H$31*(1+'W06'!$I$9:$I$31/30),0))+SUMPRODUCT(IFERROR('W06'!$H$35:$H$55*(1+'W06'!$I$35:$I$55/30),0))+SUMPRODUCT(IFERROR('W06'!$H$59:$H$85*(1+'W06'!$I$59:$I$85/30),0))+SUMPRODUCT(IFERROR('W06'!$H$89:$H$109*(1+'W06'!$I$89:$I$109/30),0)))/B10)-1,"") | G11: ='W07'!E4 | H11: =IFERROR((SUMPRODUCT(IFERROR('W07'!$H$9:$H$31*('W07'!$I$9:$I$31+'W07'!$J$9:$J$31),0))+SUMPRODUCT(IFERROR('W07'!$H$35:$H$55*('W07'!$I$35:$I$55+'W07'!$J$35:$J$55),0))+SUMPRODUCT(IFERROR('W07'!$H$59:$H$85*('W07'!$I$59:$I$85+'W07'!$J$59:$J$85),0))+SUMPRODUCT(IFERROR('W07'!$H$89:$H$109*('W07'!$I$89:$I$109+'W07'!$J$89:$J$109),0)))/(SUMPRODUCT(IFERROR('W06'!$H$9:$H$31*('W06'!$I$9:$I$31+'W06'!$J$9:$J$31),0))+SUMPRODUCT(IFERROR('W06'!$H$35:$H$55*('W06'!$I$35:$I$55+'W06'!$J$35:$J$55),0))+SUMPRODUCT(IFERROR('W06'!$H$59:$H$85*('W06'!$I$59:$I$85+'W06'!$J$59:$J$85),0))+SUMPRODUCT(IFERROR('W06'!$H$89:$H$109*('W06'!$I$89:$I$109+'W06'!$J$89:$J$109),0)))-1,"")
A12: 8 | B12: =SUM(COUNT('W08'!$H$9:$H$31),COUNT('W08'!$H$35:$H$55),COUNT('W08'!$H$59:$H$85),COUNT('W08'!$H$89:$H$109)) | C12: =(SUMPRODUCT(IFERROR('W08'!$H$9:$H$31*'W08'!$I$9:$I$31,0))+SUMPRODUCT(IFERROR('W08'!$H$35:$H$55*'W08'!$I$35:$I$55,0))+SUMPRODUCT(IFERROR('W08'!$H$59:$H$85*'W08'!$I$59:$I$85,0))+SUMPRODUCT(IFERROR('W08'!$H$89:$H$109*'W08'!$I$89:$I$109,0))) | D12: =IFERROR(C12/(SUMPRODUCT(IFERROR('W07'!$H$9:$H$31*'W07'!$I$9:$I$31,0))+SUMPRODUCT(IFERROR('W07'!$H$35:$H$55*'W07'!$I$35:$I$55,0))+SUMPRODUCT(IFERROR('W07'!$H$59:$H$85*'W07'!$I$59:$I$85,0))+SUMPRODUCT(IFERROR('W07'!$H$89:$H$109*'W07'!$I$89:$I$109,0)))-1,"") | E12: =IFERROR((SUMPRODUCT(IFERROR('W08'!$H$9:$H$31*(1+'W08'!$I$9:$I$31/30),0))+SUMPRODUCT(IFERROR('W08'!$H$35:$H$55*(1+'W08'!$I$35:$I$55/30),0))+SUMPRODUCT(IFERROR('W08'!$H$59:$H$85*(1+'W08'!$I$59:$I$85/30),0))+SUMPRODUCT(IFERROR('W08'!$H$89:$H$109*(1+'W08'!$I$89:$I$109/30),0)))/B12,"") | F12: =IFERROR(E12/((SUMPRODUCT(IFERROR('W07'!$H$9:$H$31*(1+'W07'!$I$9:$I$31/30),0))+SUMPRODUCT(IFERROR('W07'!$H$35:$H$55*(1+'W07'!$I$35:$I$55/30),0))+SUMPRODUCT(IFERROR('W07'!$H$59:$H$85*(1+'W07'!$I$59:$I$85/30),0))+SUMPRODUCT(IFERROR('W07'!$H$89:$H$109*(1+'W07'!$I$89:$I$109/30),0)))/B11)-1,"") | G12: ='W08'!E4 | H12: =IFERROR((SUMPRODUCT(IFERROR('W08'!$H$9:$H$31*('W08'!$I$9:$I$31+'W08'!$J$9:$J$31),0))+SUMPRODUCT(IFERROR('W08'!$H$35:$H$55*('W08'!$I$35:$I$55+'W08'!$J$35:$J$55),0))+SUMPRODUCT(IFERROR('W08'!$H$59:$H$85*('W08'!$I$59:$I$85+'W08'!$J$59:$J$85),0))+SUMPRODUCT(IFERROR('W08'!$H$89:$H$109*('W08'!$I$89:$I$109+'W08'!$J$89:$J$109),0)))/(SUMPRODUCT(IFERROR('W07'!$H$9:$H$31*('W07'!$I$9:$I$31+'W07'!$J$9:$J$31),0))+SUMPRODUCT(IFERROR('W07'!$H$35:$H$55*('W07'!$I$35:$I$55+'W07'!$J$35:$J$55),0))+SUMPRODUCT(IFERROR('W07'!$H$59:$H$85*('W07'!$I$59:$I$85+'W07'!$J$59:$J$85),0))+SUMPRODUCT(IFERROR('W07'!$H$89:$H$109*('W07'!$I$89:$I$109+'W07'!$J$89:$J$109),0)))-1,"")
A13: 9 | B13: =SUM(COUNT('W09'!$H$9:$H$31),COUNT('W09'!$H$35:$H$55),COUNT('W09'!$H$59:$H$85),COUNT('W09'!$H$89:$H$109)) | C13: =(SUMPRODUCT(IFERROR('W09'!$H$9:$H$31*'W09'!$I$9:$I$31,0))+SUMPRODUCT(IFERROR('W09'!$H$35:$H$55*'W09'!$I$35:$I$55,0))+SUMPRODUCT(IFERROR('W09'!$H$59:$H$85*'W09'!$I$59:$I$85,0))+SUMPRODUCT(IFERROR('W09'!$H$89:$H$109*'W09'!$I$89:$I$109,0))) | D13: =IFERROR(C13/(SUMPRODUCT(IFERROR('W08'!$H$9:$H$31*'W08'!$I$9:$I$31,0))+SUMPRODUCT(IFERROR('W08'!$H$35:$H$55*'W08'!$I$35:$I$55,0))+SUMPRODUCT(IFERROR('W08'!$H$59:$H$85*'W08'!$I$59:$I$85,0))+SUMPRODUCT(IFERROR('W08'!$H$89:$H$109*'W08'!$I$89:$I$109,0)))-1,"") | E13: =IFERROR((SUMPRODUCT(IFERROR('W09'!$H$9:$H$31*(1+'W09'!$I$9:$I$31/30),0))+SUMPRODUCT(IFERROR('W09'!$H$35:$H$55*(1+'W09'!$I$35:$I$55/30),0))+SUMPRODUCT(IFERROR('W09'!$H$59:$H$85*(1+'W09'!$I$59:$I$85/30),0))+SUMPRODUCT(IFERROR('W09'!$H$89:$H$109*(1+'W09'!$I$89:$I$109/30),0)))/B13,"") | F13: =IFERROR(E13/((SUMPRODUCT(IFERROR('W08'!$H$9:$H$31*(1+'W08'!$I$9:$I$31/30),0))+SUMPRODUCT(IFERROR('W08'!$H$35:$H$55*(1+'W08'!$I$35:$I$55/30),0))+SUMPRODUCT(IFERROR('W08'!$H$59:$H$85*(1+'W08'!$I$59:$I$85/30),0))+SUMPRODUCT(IFERROR('W08'!$H$89:$H$109*(1+'W08'!$I$89:$I$109/30),0)))/B12)-1,"") | G13: ='W09'!E4 | H13: =IFERROR((SUMPRODUCT(IFERROR('W09'!$H$9:$H$31*('W09'!$I$9:$I$31+'W09'!$J$9:$J$31),0))+SUMPRODUCT(IFERROR('W09'!$H$35:$H$55*('W09'!$I$35:$I$55+'W09'!$J$35:$J$55),0))+SUMPRODUCT(IFERROR('W09'!$H$59:$H$85*('W09'!$I$59:$I$85+'W09'!$J$59:$J$85),0))+SUMPRODUCT(IFERROR('W09'!$H$89:$H$109*('W09'!$I$89:$I$109+'W09'!$J$89:$J$109),0)))/(SUMPRODUCT(IFERROR('W08'!$H$9:$H$31*('W08'!$I$9:$I$31+'W08'!$J$9:$J$31),0))+SUMPRODUCT(IFERROR('W08'!$H$35:$H$55*('W08'!$I$35:$I$55+'W08'!$J$35:$J$55),0))+SUMPRODUCT(IFERROR('W08'!$H$59:$H$85*('W08'!$I$59:$I$85+'W08'!$J$59:$J$85),0))+SUMPRODUCT(IFERROR('W08'!$H$89:$H$109*('W08'!$I$89:$I$109+'W08'!$J$89:$J$109),0)))-1,"")
A14: 10 | B14: =SUM(COUNT('W10'!$H$9:$H$31),COUNT('W10'!$H$35:$H$55),COUNT('W10'!$H$59:$H$85),COUNT('W10'!$H$89:$H$109)) | C14: =(SUMPRODUCT(IFERROR('W10'!$H$9:$H$31*'W10'!$I$9:$I$31,0))+SUMPRODUCT(IFERROR('W10'!$H$35:$H$55*'W10'!$I$35:$I$55,0))+SUMPRODUCT(IFERROR('W10'!$H$59:$H$85*'W10'!$I$59:$I$85,0))+SUMPRODUCT(IFERROR('W10'!$H$89:$H$109*'W10'!$I$89:$I$109,0))) | D14: =IFERROR(C14/(SUMPRODUCT(IFERROR('W09'!$H$9:$H$31*'W09'!$I$9:$I$31,0))+SUMPRODUCT(IFERROR('W09'!$H$35:$H$55*'W09'!$I$35:$I$55,0))+SUMPRODUCT(IFERROR('W09'!$H$59:$H$85*'W09'!$I$59:$I$85,0))+SUMPRODUCT(IFERROR('W09'!$H$89:$H$109*'W09'!$I$89:$I$109,0)))-1,"") | E14: =IFERROR((SUMPRODUCT(IFERROR('W10'!$H$9:$H$31*(1+'W10'!$I$9:$I$31/30),0))+SUMPRODUCT(IFERROR('W10'!$H$35:$H$55*(1+'W10'!$I$35:$I$55/30),0))+SUMPRODUCT(IFERROR('W10'!$H$59:$H$85*(1+'W10'!$I$59:$I$85/30),0))+SUMPRODUCT(IFERROR('W10'!$H$89:$H$109*(1+'W10'!$I$89:$I$109/30),0)))/B14,"") | F14: =IFERROR(E14/((SUMPRODUCT(IFERROR('W09'!$H$9:$H$31*(1+'W09'!$I$9:$I$31/30),0))+SUMPRODUCT(IFERROR('W09'!$H$35:$H$55*(1+'W09'!$I$35:$I$55/30),0))+SUMPRODUCT(IFERROR('W09'!$H$59:$H$85*(1+'W09'!$I$59:$I$85/30),0))+SUMPRODUCT(IFERROR('W09'!$H$89:$H$109*(1+'W09'!$I$89:$I$109/30),0)))/B13)-1,"") | G14: ='W10'!E4 | H14: =IFERROR((SUMPRODUCT(IFERROR('W10'!$H$9:$H$31*('W10'!$I$9:$I$31+'W10'!$J$9:$J$31),0))+SUMPRODUCT(IFERROR('W10'!$H$35:$H$55*('W10'!$I$35:$I$55+'W10'!$J$35:$J$55),0))+SUMPRODUCT(IFERROR('W10'!$H$59:$H$85*('W10'!$I$59:$I$85+'W10'!$J$59:$J$85),0))+SUMPRODUCT(IFERROR('W10'!$H$89:$H$109*('W10'!$I$89:$I$109+'W10'!$J$89:$J$109),0)))/(SUMPRODUCT(IFERROR('W09'!$H$9:$H$31*('W09'!$I$9:$I$31+'W09'!$J$9:$J$31),0))+SUMPRODUCT(IFERROR('W09'!$H$35:$H$55*('W09'!$I$35:$I$55+'W09'!$J$35:$J$55),0))+SUMPRODUCT(IFERROR('W09'!$H$59:$H$85*('W09'!$I$59:$I$85+'W09'!$J$59:$J$85),0))+SUMPRODUCT(IFERROR('W09'!$H$89:$H$109*('W09'!$I$89:$I$109+'W09'!$J$89:$J$109),0)))-1,"")
A15: 11 | B15: =SUM(COUNT('W11'!$H$9:$H$31),COUNT('W11'!$H$35:$H$55),COUNT('W11'!$H$59:$H$85),COUNT('W11'!$H$89:$H$109)) | C15: =(SUMPRODUCT(IFERROR('W11'!$H$9:$H$31*'W11'!$I$9:$I$31,0))+SUMPRODUCT(IFERROR('W11'!$H$35:$H$55*'W11'!$I$35:$I$55,0))+SUMPRODUCT(IFERROR('W11'!$H$59:$H$85*'W11'!$I$59:$I$85,0))+SUMPRODUCT(IFERROR('W11'!$H$89:$H$109*'W11'!$I$89:$I$109,0))) | D15: =IFERROR(C15/(SUMPRODUCT(IFERROR('W10'!$H$9:$H$31*'W10'!$I$9:$I$31,0))+SUMPRODUCT(IFERROR('W10'!$H$35:$H$55*'W10'!$I$35:$I$55,0))+SUMPRODUCT(IFERROR('W10'!$H$59:$H$85*'W10'!$I$59:$I$85,0))+SUMPRODUCT(IFERROR('W10'!$H$89:$H$109*'W10'!$I$89:$I$109,0)))-1,"") | E15: =IFERROR((SUMPRODUCT(IFERROR('W11'!$H$9:$H$31*(1+'W11'!$I$9:$I$31/30),0))+SUMPRODUCT(IFERROR('W11'!$H$35:$H$55*(1+'W11'!$I$35:$I$55/30),0))+SUMPRODUCT(IFERROR('W11'!$H$59:$H$85*(1+'W11'!$I$59:$I$85/30),0))+SUMPRODUCT(IFERROR('W11'!$H$89:$H$109*(1+'W11'!$I$89:$I$109/30),0)))/B15,"") | F15: =IFERROR(E15/((SUMPRODUCT(IFERROR('W10'!$H$9:$H$31*(1+'W10'!$I$9:$I$31/30),0))+SUMPRODUCT(IFERROR('W10'!$H$35:$H$55*(1+'W10'!$I$35:$I$55/30),0))+SUMPRODUCT(IFERROR('W10'!$H$59:$H$85*(1+'W10'!$I$59:$I$85/30),0))+SUMPRODUCT(IFERROR('W10'!$H$89:$H$109*(1+'W10'!$I$89:$I$109/30),0)))/B14)-1,"") | G15: ='W11'!E4 | H15: =IFERROR((SUMPRODUCT(IFERROR('W11'!$H$9:$H$31*('W11'!$I$9:$I$31+'W11'!$J$9:$J$31),0))+SUMPRODUCT(IFERROR('W11'!$H$35:$H$55*('W11'!$I$35:$I$55+'W11'!$J$35:$J$55),0))+SUMPRODUCT(IFERROR('W11'!$H$59:$H$85*('W11'!$I$59:$I$85+'W11'!$J$59:$J$85),0))+SUMPRODUCT(IFERROR('W11'!$H$89:$H$109*('W11'!$I$89:$I$109+'W11'!$J$89:$J$109),0)))/(SUMPRODUCT(IFERROR('W10'!$H$9:$H$31*('W10'!$I$9:$I$31+'W10'!$J$9:$J$31),0))+SUMPRODUCT(IFERROR('W10'!$H$35:$H$55*('W10'!$I$35:$I$55+'W10'!$J$35:$J$55),0))+SUMPRODUCT(IFERROR('W10'!$H$59:$H$85*('W10'!$I$59:$I$85+'W10'!$J$59:$J$85),0))+SUMPRODUCT(IFERROR('W10'!$H$89:$H$109*('W10'!$I$89:$I$109+'W10'!$J$89:$J$109),0)))-1,"")
A16: 12 | B16: =SUM(COUNT('W12'!$H$9:$H$31),COUNT('W12'!$H$35:$H$55),COUNT('W12'!$H$59:$H$85),COUNT('W12'!$H$89:$H$109)) | C16: =(SUMPRODUCT(IFERROR('W12'!$H$9:$H$31*'W12'!$I$9:$I$31,0))+SUMPRODUCT(IFERROR('W12'!$H$35:$H$55*'W12'!$I$35:$I$55,0))+SUMPRODUCT(IFERROR('W12'!$H$59:$H$85*'W12'!$I$59:$I$85,0))+SUMPRODUCT(IFERROR('W12'!$H$89:$H$109*'W12'!$I$89:$I$109,0))) | D16: =IFERROR(C16/(SUMPRODUCT(IFERROR('W11'!$H$9:$H$31*'W11'!$I$9:$I$31,0))+SUMPRODUCT(IFERROR('W11'!$H$35:$H$55*'W11'!$I$35:$I$55,0))+SUMPRODUCT(IFERROR('W11'!$H$59:$H$85*'W11'!$I$59:$I$85,0))+SUMPRODUCT(IFERROR('W11'!$H$89:$H$109*'W11'!$I$89:$I$109,0)))-1,"") | E16: =IFERROR((SUMPRODUCT(IFERROR('W12'!$H$9:$H$31*(1+'W12'!$I$9:$I$31/30),0))+SUMPRODUCT(IFERROR('W12'!$H$35:$H$55*(1+'W12'!$I$35:$I$55/30),0))+SUMPRODUCT(IFERROR('W12'!$H$59:$H$85*(1+'W12'!$I$59:$I$85/30),0))+SUMPRODUCT(IFERROR('W12'!$H$89:$H$109*(1+'W12'!$I$89:$I$109/30),0)))/B16,"") | F16: =IFERROR(E16/((SUMPRODUCT(IFERROR('W11'!$H$9:$H$31*(1+'W11'!$I$9:$I$31/30),0))+SUMPRODUCT(IFERROR('W11'!$H$35:$H$55*(1+'W11'!$I$35:$I$55/30),0))+SUMPRODUCT(IFERROR('W11'!$H$59:$H$85*(1+'W11'!$I$59:$I$85/30),0))+SUMPRODUCT(IFERROR('W11'!$H$89:$H$109*(1+'W11'!$I$89:$I$109/30),0)))/B15)-1,"") | G16: ='W12'!E4 | H16: =IFERROR((SUMPRODUCT(IFERROR('W12'!$H$9:$H$31*('W12'!$I$9:$I$31+'W12'!$J$9:$J$31),0))+SUMPRODUCT(IFERROR('W12'!$H$35:$H$55*('W12'!$I$35:$I$55+'W12'!$J$35:$J$55),0))+SUMPRODUCT(IFERROR('W12'!$H$59:$H$85*('W12'!$I$59:$I$85+'W12'!$J$59:$J$85),0))+SUMPRODUCT(IFERROR('W12'!$H$89:$H$109*('W12'!$I$89:$I$109+'W12'!$J$89:$J$109),0)))/(SUMPRODUCT(IFERROR('W11'!$H$9:$H$31*('W11'!$I$9:$I$31+'W11'!$J$9:$J$31),0))+SUMPRODUCT(IFERROR('W11'!$H$35:$H$55*('W11'!$I$35:$I$55+'W11'!$J$35:$J$55),0))+SUMPRODUCT(IFERROR('W11'!$H$59:$H$85*('W11'!$I$59:$I$85+'W11'!$J$59:$J$85),0))+SUMPRODUCT(IFERROR('W11'!$H$89:$H$109*('W11'!$I$89:$I$109+'W11'!$J$89:$J$109),0)))-1,"")
A17: 13 | B17: =SUM(COUNT('W13'!$H$9:$H$31),COUNT('W13'!$H$35:$H$55),COUNT('W13'!$H$59:$H$85),COUNT('W13'!$H$89:$H$109)) | C17: =(SUMPRODUCT(IFERROR('W13'!$H$9:$H$31*'W13'!$I$9:$I$31,0))+SUMPRODUCT(IFERROR('W13'!$H$35:$H$55*'W13'!$I$35:$I$55,0))+SUMPRODUCT(IFERROR('W13'!$H$59:$H$85*'W13'!$I$59:$I$85,0))+SUMPRODUCT(IFERROR('W13'!$H$89:$H$109*'W13'!$I$89:$I$109,0))) | D17: =IFERROR(C17/(SUMPRODUCT(IFERROR('W12'!$H$9:$H$31*'W12'!$I$9:$I$31,0))+SUMPRODUCT(IFERROR('W12'!$H$35:$H$55*'W12'!$I$35:$I$55,0))+SUMPRODUCT(IFERROR('W12'!$H$59:$H$85*'W12'!$I$59:$I$85,0))+SUMPRODUCT(IFERROR('W12'!$H$89:$H$109*'W12'!$I$89:$I$109,0)))-1,"") | E17: =IFERROR((SUMPRODUCT(IFERROR('W13'!$H$9:$H$31*(1+'W13'!$I$9:$I$31/30),0))+SUMPRODUCT(IFERROR('W13'!$H$35:$H$55*(1+'W13'!$I$35:$I$55/30),0))+SUMPRODUCT(IFERROR('W13'!$H$59:$H$85*(1+'W13'!$I$59:$I$85/30),0))+SUMPRODUCT(IFERROR('W13'!$H$89:$H$109*(1+'W13'!$I$89:$I$109/30),0)))/B17,"") | F17: =IFERROR(E17/((SUMPRODUCT(IFERROR('W12'!$H$9:$H$31*(1+'W12'!$I$9:$I$31/30),0))+SUMPRODUCT(IFERROR('W12'!$H$35:$H$55*(1+'W12'!$I$35:$I$55/30),0))+SUMPRODUCT(IFERROR('W12'!$H$59:$H$85*(1+'W12'!$I$59:$I$85/30),0))+SUMPRODUCT(IFERROR('W12'!$H$89:$H$109*(1+'W12'!$I$89:$I$109/30),0)))/B16)-1,"") | G17: ='W13'!E4 | H17: =IFERROR((SUMPRODUCT(IFERROR('W13'!$H$9:$H$31*('W13'!$I$9:$I$31+'W13'!$J$9:$J$31),0))+SUMPRODUCT(IFERROR('W13'!$H$35:$H$55*('W13'!$I$35:$I$55+'W13'!$J$35:$J$55),0))+SUMPRODUCT(IFERROR('W13'!$H$59:$H$85*('W13'!$I$59:$I$85+'W13'!$J$59:$J$85),0))+SUMPRODUCT(IFERROR('W13'!$H$89:$H$109*('W13'!$I$89:$I$109+'W13'!$J$89:$J$109),0)))/(SUMPRODUCT(IFERROR('W12'!$H$9:$H$31*('W12'!$I$9:$I$31+'W12'!$J$9:$J$31),0))+SUMPRODUCT(IFERROR('W12'!$H$35:$H$55*('W12'!$I$35:$I$55+'W12'!$J$35:$J$55),0))+SUMPRODUCT(IFERROR('W12'!$H$59:$H$85*('W12'!$I$59:$I$85+'W12'!$J$59:$J$85),0))+SUMPRODUCT(IFERROR('W12'!$H$89:$H$109*('W12'!$I$89:$I$109+'W12'!$J$89:$J$109),0)))-1,"")
A18: 14 | B18: =SUM(COUNT('W14'!$H$9:$H$31),COUNT('W14'!$H$35:$H$55),COUNT('W14'!$H$59:$H$85),COUNT('W14'!$H$89:$H$109)) | C18: =(SUMPRODUCT(IFERROR('W14'!$H$9:$H$31*'W14'!$I$9:$I$31,0))+SUMPRODUCT(IFERROR('W14'!$H$35:$H$55*'W14'!$I$35:$I$55,0))+SUMPRODUCT(IFERROR('W14'!$H$59:$H$85*'W14'!$I$59:$I$85,0))+SUMPRODUCT(IFERROR('W14'!$H$89:$H$109*'W14'!$I$89:$I$109,0))) | D18: =IFERROR(C18/(SUMPRODUCT(IFERROR('W13'!$H$9:$H$31*'W13'!$I$9:$I$31,0))+SUMPRODUCT(IFERROR('W13'!$H$35:$H$55*'W13'!$I$35:$I$55,0))+SUMPRODUCT(IFERROR('W13'!$H$59:$H$85*'W13'!$I$59:$I$85,0))+SUMPRODUCT(IFERROR('W13'!$H$89:$H$109*'W13'!$I$89:$I$109,0)))-1,"") | E18: =IFERROR((SUMPRODUCT(IFERROR('W14'!$H$9:$H$31*(1+'W14'!$I$9:$I$31/30),0))+SUMPRODUCT(IFERROR('W14'!$H$35:$H$55*(1+'W14'!$I$35:$I$55/30),0))+SUMPRODUCT(IFERROR('W14'!$H$59:$H$85*(1+'W14'!$I$59:$I$85/30),0))+SUMPRODUCT(IFERROR('W14'!$H$89:$H$109*(1+'W14'!$I$89:$I$109/30),0)))/B18,"") | F18: =IFERROR(E18/((SUMPRODUCT(IFERROR('W13'!$H$9:$H$31*(1+'W13'!$I$9:$I$31/30),0))+SUMPRODUCT(IFERROR('W13'!$H$35:$H$55*(1+'W13'!$I$35:$I$55/30),0))+SUMPRODUCT(IFERROR('W13'!$H$59:$H$85*(1+'W13'!$I$59:$I$85/30),0))+SUMPRODUCT(IFERROR('W13'!$H$89:$H$109*(1+'W13'!$I$89:$I$109/30),0)))/B17)-1,"") | G18: ='W14'!E4 | H18: =IFERROR((SUMPRODUCT(IFERROR('W14'!$H$9:$H$31*('W14'!$I$9:$I$31+'W14'!$J$9:$J$31),0))+SUMPRODUCT(IFERROR('W14'!$H$35:$H$55*('W14'!$I$35:$I$55+'W14'!$J$35:$J$55),0))+SUMPRODUCT(IFERROR('W14'!$H$59:$H$85*('W14'!$I$59:$I$85+'W14'!$J$59:$J$85),0))+SUMPRODUCT(IFERROR('W14'!$H$89:$H$109*('W14'!$I$89:$I$109+'W14'!$J$89:$J$109),0)))/(SUMPRODUCT(IFERROR('W13'!$H$9:$H$31*('W13'!$I$9:$I$31+'W13'!$J$9:$J$31),0))+SUMPRODUCT(IFERROR('W13'!$H$35:$H$55*('W13'!$I$35:$I$55+'W13'!$J$35:$J$55),0))+SUMPRODUCT(IFERROR('W13'!$H$59:$H$85*('W13'!$I$59:$I$85+'W13'!$J$59:$J$85),0))+SUMPRODUCT(IFERROR('W13'!$H$89:$H$109*('W13'!$I$89:$I$109+'W13'!$J$89:$J$109),0)))-1,"")
A19: 15 | B19: =SUM(COUNT('W15'!$H$9:$H$31),COUNT('W15'!$H$35:$H$55),COUNT('W15'!$H$59:$H$85),COUNT('W15'!$H$89:$H$109)) | C19: =(SUMPRODUCT(IFERROR('W15'!$H$9:$H$31*'W15'!$I$9:$I$31,0))+SUMPRODUCT(IFERROR('W15'!$H$35:$H$55*'W15'!$I$35:$I$55,0))+SUMPRODUCT(IFERROR('W15'!$H$59:$H$85*'W15'!$I$59:$I$85,0))+SUMPRODUCT(IFERROR('W15'!$H$89:$H$109*'W15'!$I$89:$I$109,0))) | D19: =IFERROR(C19/(SUMPRODUCT(IFERROR('W14'!$H$9:$H$31*'W14'!$I$9:$I$31,0))+SUMPRODUCT(IFERROR('W14'!$H$35:$H$55*'W14'!$I$35:$I$55,0))+SUMPRODUCT(IFERROR('W14'!$H$59:$H$85*'W14'!$I$59:$I$85,0))+SUMPRODUCT(IFERROR('W14'!$H$89:$H$109*'W14'!$I$89:$I$109,0)))-1,"") | E19: =IFERROR((SUMPRODUCT(IFERROR('W15'!$H$9:$H$31*(1+'W15'!$I$9:$I$31/30),0))+SUMPRODUCT(IFERROR('W15'!$H$35:$H$55*(1+'W15'!$I$35:$I$55/30),0))+SUMPRODUCT(IFERROR('W15'!$H$59:$H$85*(1+'W15'!$I$59:$I$85/30),0))+SUMPRODUCT(IFERROR('W15'!$H$89:$H$109*(1+'W15'!$I$89:$I$109/30),0)))/B19,"") | F19: =IFERROR(E19/((SUMPRODUCT(IFERROR('W14'!$H$9:$H$31*(1+'W14'!$I$9:$I$31/30),0))+SUMPRODUCT(IFERROR('W14'!$H$35:$H$55*(1+'W14'!$I$35:$I$55/30),0))+SUMPRODUCT(IFERROR('W14'!$H$59:$H$85*(1+'W14'!$I$59:$I$85/30),0))+SUMPRODUCT(IFERROR('W14'!$H$89:$H$109*(1+'W14'!$I$89:$I$109/30),0)))/B18)-1,"") | G19: ='W15'!E4 | H19: =IFERROR((SUMPRODUCT(IFERROR('W15'!$H$9:$H$31*('W15'!$I$9:$I$31+'W15'!$J$9:$J$31),0))+SUMPRODUCT(IFERROR('W15'!$H$35:$H$55*('W15'!$I$35:$I$55+'W15'!$J$35:$J$55),0))+SUMPRODUCT(IFERROR('W15'!$H$59:$H$85*('W15'!$I$59:$I$85+'W15'!$J$59:$J$85),0))+SUMPRODUCT(IFERROR('W15'!$H$89:$H$109*('W15'!$I$89:$I$109+'W15'!$J$89:$J$109),0)))/(SUMPRODUCT(IFERROR('W14'!$H$9:$H$31*('W14'!$I$9:$I$31+'W14'!$J$9:$J$31),0))+SUMPRODUCT(IFERROR('W14'!$H$35:$H$55*('W14'!$I$35:$I$55+'W14'!$J$35:$J$55),0))+SUMPRODUCT(IFERROR('W14'!$H$59:$H$85*('W14'!$I$59:$I$85+'W14'!$J$59:$J$85),0))+SUMPRODUCT(IFERROR('W14'!$H$89:$H$109*('W14'!$I$89:$I$109+'W14'!$J$89:$J$109),0)))-1,"")
A20: 16 | B20: =SUM(COUNT('W16'!$H$9:$H$31),COUNT('W16'!$H$35:$H$55),COUNT('W16'!$H$59:$H$85),COUNT('W16'!$H$89:$H$109)) | C20: =(SUMPRODUCT(IFERROR('W16'!$H$9:$H$31*'W16'!$I$9:$I$31,0))+SUMPRODUCT(IFERROR('W16'!$H$35:$H$55*'W16'!$I$35:$I$55,0))+SUMPRODUCT(IFERROR('W16'!$H$59:$H$85*'W16'!$I$59:$I$85,0))+SUMPRODUCT(IFERROR('W16'!$H$89:$H$109*'W16'!$I$89:$I$109,0))) | D20: =IFERROR(C20/(SUMPRODUCT(IFERROR('W15'!$H$9:$H$31*'W15'!$I$9:$I$31,0))+SUMPRODUCT(IFERROR('W15'!$H$35:$H$55*'W15'!$I$35:$I$55,0))+SUMPRODUCT(IFERROR('W15'!$H$59:$H$85*'W15'!$I$59:$I$85,0))+SUMPRODUCT(IFERROR('W15'!$H$89:$H$109*'W15'!$I$89:$I$109,0)))-1,"") | E20: =IFERROR((SUMPRODUCT(IFERROR('W16'!$H$9:$H$31*(1+'W16'!$I$9:$I$31/30),0))+SUMPRODUCT(IFERROR('W16'!$H$35:$H$55*(1+'W16'!$I$35:$I$55/30),0))+SUMPRODUCT(IFERROR('W16'!$H$59:$H$85*(1+'W16'!$I$59:$I$85/30),0))+SUMPRODUCT(IFERROR('W16'!$H$89:$H$109*(1+'W16'!$I$89:$I$109/30),0)))/B20,"") | F20: =IFERROR(E20/((SUMPRODUCT(IFERROR('W15'!$H$9:$H$31*(1+'W15'!$I$9:$I$31/30),0))+SUMPRODUCT(IFERROR('W15'!$H$35:$H$55*(1+'W15'!$I$35:$I$55/30),0))+SUMPRODUCT(IFERROR('W15'!$H$59:$H$85*(1+'W15'!$I$59:$I$85/30),0))+SUMPRODUCT(IFERROR('W15'!$H$89:$H$109*(1+'W15'!$I$89:$I$109/30),0)))/B19)-1,"") | G20: ='W16'!E4 | H20: =IFERROR((SUMPRODUCT(IFERROR('W16'!$H$9:$H$31*('W16'!$I$9:$I$31+'W16'!$J$9:$J$31),0))+SUMPRODUCT(IFERROR('W16'!$H$35:$H$55*('W16'!$I$35:$I$55+'W16'!$J$35:$J$55),0))+SUMPRODUCT(IFERROR('W16'!$H$59:$H$85*('W16'!$I$59:$I$85+'W16'!$J$59:$J$85),0))+SUMPRODUCT(IFERROR('W16'!$H$89:$H$109*('W16'!$I$89:$I$109+'W16'!$J$89:$J$109),0)))/(SUMPRODUCT(IFERROR('W15'!$H$9:$H$31*('W15'!$I$9:$I$31+'W15'!$J$9:$J$31),0))+SUMPRODUCT(IFERROR('W15'!$H$35:$H$55*('W15'!$I$35:$I$55+'W15'!$J$35:$J$55),0))+SUMPRODUCT(IFERROR('W15'!$H$59:$H$85*('W15'!$I$59:$I$85+'W15'!$J$59:$J$85),0))+SUMPRODUCT(IFERROR('W15'!$H$89:$H$109*('W15'!$I$89:$I$109+'W15'!$J$89:$J$109),0)))-1,"")
A22: CONTROLLO FORMULE | B22: Performance RIR-adjusted = Σ[carico × (reps + RIR)]. Volume = Σ[carico × reps]. I confronti per esercizio e giorno seguono il nome/ID reale, quindi restano corretti anche nelle settimane di deload con righe spostate.
A23: PERFORMANCE PER GIORNO • RIR-ADJUSTED vs PRECEDENTE
A24: SETTIMANA | B24: UPPER A | C24: LOWER A | D24: UPPER B | E24: LOWER B
A25: 1 | B25: ="" | C25: ="" | D25: ="" | E25: =""
A26: 2 | B26: =IFERROR(SUMPRODUCT(IFERROR(--('W02'!$N$9:$N$109="G1")*'W02'!$H$9:$H$109*('W02'!$I$9:$I$109+'W02'!$J$9:$J$109),0))/SUMPRODUCT(IFERROR(--('W01'!$N$9:$N$109="G1")*'W01'!$H$9:$H$109*('W01'!$I$9:$I$109+'W01'!$J$9:$J$109),0))-1,"") | C26: =IFERROR(SUMPRODUCT(IFERROR(--('W02'!$N$9:$N$109="G2")*'W02'!$H$9:$H$109*('W02'!$I$9:$I$109+'W02'!$J$9:$J$109),0))/SUMPRODUCT(IFERROR(--('W01'!$N$9:$N$109="G2")*'W01'!$H$9:$H$109*('W01'!$I$9:$I$109+'W01'!$J$9:$J$109),0))-1,"") | D26: =IFERROR(SUMPRODUCT(IFERROR(--('W02'!$N$9:$N$109="G3")*'W02'!$H$9:$H$109*('W02'!$I$9:$I$109+'W02'!$J$9:$J$109),0))/SUMPRODUCT(IFERROR(--('W01'!$N$9:$N$109="G3")*'W01'!$H$9:$H$109*('W01'!$I$9:$I$109+'W01'!$J$9:$J$109),0))-1,"") | E26: =IFERROR(SUMPRODUCT(IFERROR(--('W02'!$N$9:$N$109="G4")*'W02'!$H$9:$H$109*('W02'!$I$9:$I$109+'W02'!$J$9:$J$109),0))/SUMPRODUCT(IFERROR(--('W01'!$N$9:$N$109="G4")*'W01'!$H$9:$H$109*('W01'!$I$9:$I$109+'W01'!$J$9:$J$109),0))-1,"")
A27: 3 | B27: =IFERROR(SUMPRODUCT(IFERROR(--('W03'!$N$9:$N$109="G1")*'W03'!$H$9:$H$109*('W03'!$I$9:$I$109+'W03'!$J$9:$J$109),0))/SUMPRODUCT(IFERROR(--('W02'!$N$9:$N$109="G1")*'W02'!$H$9:$H$109*('W02'!$I$9:$I$109+'W02'!$J$9:$J$109),0))-1,"") | C27: =IFERROR(SUMPRODUCT(IFERROR(--('W03'!$N$9:$N$109="G2")*'W03'!$H$9:$H$109*('W03'!$I$9:$I$109+'W03'!$J$9:$J$109),0))/SUMPRODUCT(IFERROR(--('W02'!$N$9:$N$109="G2")*'W02'!$H$9:$H$109*('W02'!$I$9:$I$109+'W02'!$J$9:$J$109),0))-1,"") | D27: =IFERROR(SUMPRODUCT(IFERROR(--('W03'!$N$9:$N$109="G3")*'W03'!$H$9:$H$109*('W03'!$I$9:$I$109+'W03'!$J$9:$J$109),0))/SUMPRODUCT(IFERROR(--('W02'!$N$9:$N$109="G3")*'W02'!$H$9:$H$109*('W02'!$I$9:$I$109+'W02'!$J$9:$J$109),0))-1,"") | E27: =IFERROR(SUMPRODUCT(IFERROR(--('W03'!$N$9:$N$109="G4")*'W03'!$H$9:$H$109*('W03'!$I$9:$I$109+'W03'!$J$9:$J$109),0))/SUMPRODUCT(IFERROR(--('W02'!$N$9:$N$109="G4")*'W02'!$H$9:$H$109*('W02'!$I$9:$I$109+'W02'!$J$9:$J$109),0))-1,"")
A28: 4 | B28: =IFERROR(SUMPRODUCT(IFERROR(--('W04'!$N$9:$N$109="G1")*'W04'!$H$9:$H$109*('W04'!$I$9:$I$109+'W04'!$J$9:$J$109),0))/SUMPRODUCT(IFERROR(--('W03'!$N$9:$N$109="G1")*'W03'!$H$9:$H$109*('W03'!$I$9:$I$109+'W03'!$J$9:$J$109),0))-1,"") | C28: =IFERROR(SUMPRODUCT(IFERROR(--('W04'!$N$9:$N$109="G2")*'W04'!$H$9:$H$109*('W04'!$I$9:$I$109+'W04'!$J$9:$J$109),0))/SUMPRODUCT(IFERROR(--('W03'!$N$9:$N$109="G2")*'W03'!$H$9:$H$109*('W03'!$I$9:$I$109+'W03'!$J$9:$J$109),0))-1,"") | D28: =IFERROR(SUMPRODUCT(IFERROR(--('W04'!$N$9:$N$109="G3")*'W04'!$H$9:$H$109*('W04'!$I$9:$I$109+'W04'!$J$9:$J$109),0))/SUMPRODUCT(IFERROR(--('W03'!$N$9:$N$109="G3")*'W03'!$H$9:$H$109*('W03'!$I$9:$I$109+'W03'!$J$9:$J$109),0))-1,"") | E28: =IFERROR(SUMPRODUCT(IFERROR(--('W04'!$N$9:$N$109="G4")*'W04'!$H$9:$H$109*('W04'!$I$9:$I$109+'W04'!$J$9:$J$109),0))/SUMPRODUCT(IFERROR(--('W03'!$N$9:$N$109="G4")*'W03'!$H$9:$H$109*('W03'!$I$9:$I$109+'W03'!$J$9:$J$109),0))-1,"")
A29: 5 | B29: =IFERROR(SUMPRODUCT(IFERROR(--('W05'!$N$9:$N$109="G1")*'W05'!$H$9:$H$109*('W05'!$I$9:$I$109+'W05'!$J$9:$J$109),0))/SUMPRODUCT(IFERROR(--('W04'!$N$9:$N$109="G1")*'W04'!$H$9:$H$109*('W04'!$I$9:$I$109+'W04'!$J$9:$J$109),0))-1,"") | C29: =IFERROR(SUMPRODUCT(IFERROR(--('W05'!$N$9:$N$109="G2")*'W05'!$H$9:$H$109*('W05'!$I$9:$I$109+'W05'!$J$9:$J$109),0))/SUMPRODUCT(IFERROR(--('W04'!$N$9:$N$109="G2")*'W04'!$H$9:$H$109*('W04'!$I$9:$I$109+'W04'!$J$9:$J$109),0))-1,"") | D29: =IFERROR(SUMPRODUCT(IFERROR(--('W05'!$N$9:$N$109="G3")*'W05'!$H$9:$H$109*('W05'!$I$9:$I$109+'W05'!$J$9:$J$109),0))/SUMPRODUCT(IFERROR(--('W04'!$N$9:$N$109="G3")*'W04'!$H$9:$H$109*('W04'!$I$9:$I$109+'W04'!$J$9:$J$109),0))-1,"") | E29: =IFERROR(SUMPRODUCT(IFERROR(--('W05'!$N$9:$N$109="G4")*'W05'!$H$9:$H$109*('W05'!$I$9:$I$109+'W05'!$J$9:$J$109),0))/SUMPRODUCT(IFERROR(--('W04'!$N$9:$N$109="G4")*'W04'!$H$9:$H$109*('W04'!$I$9:$I$109+'W04'!$J$9:$J$109),0))-1,"")
A30: 6 | B30: =IFERROR(SUMPRODUCT(IFERROR(--('W06'!$N$9:$N$109="G1")*'W06'!$H$9:$H$109*('W06'!$I$9:$I$109+'W06'!$J$9:$J$109),0))/SUMPRODUCT(IFERROR(--('W05'!$N$9:$N$109="G1")*'W05'!$H$9:$H$109*('W05'!$I$9:$I$109+'W05'!$J$9:$J$109),0))-1,"") | C30: =IFERROR(SUMPRODUCT(IFERROR(--('W06'!$N$9:$N$109="G2")*'W06'!$H$9:$H$109*('W06'!$I$9:$I$109+'W06'!$J$9:$J$109),0))/SUMPRODUCT(IFERROR(--('W05'!$N$9:$N$109="G2")*'W05'!$H$9:$H$109*('W05'!$I$9:$I$109+'W05'!$J$9:$J$109),0))-1,"") | D30: =IFERROR(SUMPRODUCT(IFERROR(--('W06'!$N$9:$N$109="G3")*'W06'!$H$9:$H$109*('W06'!$I$9:$I$109+'W06'!$J$9:$J$109),0))/SUMPRODUCT(IFERROR(--('W05'!$N$9:$N$109="G3")*'W05'!$H$9:$H$109*('W05'!$I$9:$I$109+'W05'!$J$9:$J$109),0))-1,"") | E30: =IFERROR(SUMPRODUCT(IFERROR(--('W06'!$N$9:$N$109="G4")*'W06'!$H$9:$H$109*('W06'!$I$9:$I$109+'W06'!$J$9:$J$109),0))/SUMPRODUCT(IFERROR(--('W05'!$N$9:$N$109="G4")*'W05'!$H$9:$H$109*('W05'!$I$9:$I$109+'W05'!$J$9:$J$109),0))-1,"")
A31: 7 | B31: =IFERROR(SUMPRODUCT(IFERROR(--('W07'!$N$9:$N$109="G1")*'W07'!$H$9:$H$109*('W07'!$I$9:$I$109+'W07'!$J$9:$J$109),0))/SUMPRODUCT(IFERROR(--('W06'!$N$9:$N$109="G1")*'W06'!$H$9:$H$109*('W06'!$I$9:$I$109+'W06'!$J$9:$J$109),0))-1,"") | C31: =IFERROR(SUMPRODUCT(IFERROR(--('W07'!$N$9:$N$109="G2")*'W07'!$H$9:$H$109*('W07'!$I$9:$I$109+'W07'!$J$9:$J$109),0))/SUMPRODUCT(IFERROR(--('W06'!$N$9:$N$109="G2")*'W06'!$H$9:$H$109*('W06'!$I$9:$I$109+'W06'!$J$9:$J$109),0))-1,"") | D31: =IFERROR(SUMPRODUCT(IFERROR(--('W07'!$N$9:$N$109="G3")*'W07'!$H$9:$H$109*('W07'!$I$9:$I$109+'W07'!$J$9:$J$109),0))/SUMPRODUCT(IFERROR(--('W06'!$N$9:$N$109="G3")*'W06'!$H$9:$H$109*('W06'!$I$9:$I$109+'W06'!$J$9:$J$109),0))-1,"") | E31: =IFERROR(SUMPRODUCT(IFERROR(--('W07'!$N$9:$N$109="G4")*'W07'!$H$9:$H$109*('W07'!$I$9:$I$109+'W07'!$J$9:$J$109),0))/SUMPRODUCT(IFERROR(--('W06'!$N$9:$N$109="G4")*'W06'!$H$9:$H$109*('W06'!$I$9:$I$109+'W06'!$J$9:$J$109),0))-1,"")
A32: 8 | B32: =IFERROR(SUMPRODUCT(IFERROR(--('W08'!$N$9:$N$109="G1")*'W08'!$H$9:$H$109*('W08'!$I$9:$I$109+'W08'!$J$9:$J$109),0))/SUMPRODUCT(IFERROR(--('W07'!$N$9:$N$109="G1")*'W07'!$H$9:$H$109*('W07'!$I$9:$I$109+'W07'!$J$9:$J$109),0))-1,"") | C32: =IFERROR(SUMPRODUCT(IFERROR(--('W08'!$N$9:$N$109="G2")*'W08'!$H$9:$H$109*('W08'!$I$9:$I$109+'W08'!$J$9:$J$109),0))/SUMPRODUCT(IFERROR(--('W07'!$N$9:$N$109="G2")*'W07'!$H$9:$H$109*('W07'!$I$9:$I$109+'W07'!$J$9:$J$109),0))-1,"") | D32: =IFERROR(SUMPRODUCT(IFERROR(--('W08'!$N$9:$N$109="G3")*'W08'!$H$9:$H$109*('W08'!$I$9:$I$109+'W08'!$J$9:$J$109),0))/SUMPRODUCT(IFERROR(--('W07'!$N$9:$N$109="G3")*'W07'!$H$9:$H$109*('W07'!$I$9:$I$109+'W07'!$J$9:$J$109),0))-1,"") | E32: =IFERROR(SUMPRODUCT(IFERROR(--('W08'!$N$9:$N$109="G4")*'W08'!$H$9:$H$109*('W08'!$I$9:$I$109+'W08'!$J$9:$J$109),0))/SUMPRODUCT(IFERROR(--('W07'!$N$9:$N$109="G4")*'W07'!$H$9:$H$109*('W07'!$I$9:$I$109+'W07'!$J$9:$J$109),0))-1,"")
A33: 9 | B33: =IFERROR(SUMPRODUCT(IFERROR(--('W09'!$N$9:$N$109="G1")*'W09'!$H$9:$H$109*('W09'!$I$9:$I$109+'W09'!$J$9:$J$109),0))/SUMPRODUCT(IFERROR(--('W08'!$N$9:$N$109="G1")*'W08'!$H$9:$H$109*('W08'!$I$9:$I$109+'W08'!$J$9:$J$109),0))-1,"") | C33: =IFERROR(SUMPRODUCT(IFERROR(--('W09'!$N$9:$N$109="G2")*'W09'!$H$9:$H$109*('W09'!$I$9:$I$109+'W09'!$J$9:$J$109),0))/SUMPRODUCT(IFERROR(--('W08'!$N$9:$N$109="G2")*'W08'!$H$9:$H$109*('W08'!$I$9:$I$109+'W08'!$J$9:$J$109),0))-1,"") | D33: =IFERROR(SUMPRODUCT(IFERROR(--('W09'!$N$9:$N$109="G3")*'W09'!$H$9:$H$109*('W09'!$I$9:$I$109+'W09'!$J$9:$J$109),0))/SUMPRODUCT(IFERROR(--('W08'!$N$9:$N$109="G3")*'W08'!$H$9:$H$109*('W08'!$I$9:$I$109+'W08'!$J$9:$J$109),0))-1,"") | E33: =IFERROR(SUMPRODUCT(IFERROR(--('W09'!$N$9:$N$109="G4")*'W09'!$H$9:$H$109*('W09'!$I$9:$I$109+'W09'!$J$9:$J$109),0))/SUMPRODUCT(IFERROR(--('W08'!$N$9:$N$109="G4")*'W08'!$H$9:$H$109*('W08'!$I$9:$I$109+'W08'!$J$9:$J$109),0))-1,"")
A34: 10 | B34: =IFERROR(SUMPRODUCT(IFERROR(--('W10'!$N$9:$N$109="G1")*'W10'!$H$9:$H$109*('W10'!$I$9:$I$109+'W10'!$J$9:$J$109),0))/SUMPRODUCT(IFERROR(--('W09'!$N$9:$N$109="G1")*'W09'!$H$9:$H$109*('W09'!$I$9:$I$109+'W09'!$J$9:$J$109),0))-1,"") | C34: =IFERROR(SUMPRODUCT(IFERROR(--('W10'!$N$9:$N$109="G2")*'W10'!$H$9:$H$109*('W10'!$I$9:$I$109+'W10'!$J$9:$J$109),0))/SUMPRODUCT(IFERROR(--('W09'!$N$9:$N$109="G2")*'W09'!$H$9:$H$109*('W09'!$I$9:$I$109+'W09'!$J$9:$J$109),0))-1,"") | D34: =IFERROR(SUMPRODUCT(IFERROR(--('W10'!$N$9:$N$109="G3")*'W10'!$H$9:$H$109*('W10'!$I$9:$I$109+'W10'!$J$9:$J$109),0))/SUMPRODUCT(IFERROR(--('W09'!$N$9:$N$109="G3")*'W09'!$H$9:$H$109*('W09'!$I$9:$I$109+'W09'!$J$9:$J$109),0))-1,"") | E34: =IFERROR(SUMPRODUCT(IFERROR(--('W10'!$N$9:$N$109="G4")*'W10'!$H$9:$H$109*('W10'!$I$9:$I$109+'W10'!$J$9:$J$109),0))/SUMPRODUCT(IFERROR(--('W09'!$N$9:$N$109="G4")*'W09'!$H$9:$H$109*('W09'!$I$9:$I$109+'W09'!$J$9:$J$109),0))-1,"")
A35: 11 | B35: =IFERROR(SUMPRODUCT(IFERROR(--('W11'!$N$9:$N$109="G1")*'W11'!$H$9:$H$109*('W11'!$I$9:$I$109+'W11'!$J$9:$J$109),0))/SUMPRODUCT(IFERROR(--('W10'!$N$9:$N$109="G1")*'W10'!$H$9:$H$109*('W10'!$I$9:$I$109+'W10'!$J$9:$J$109),0))-1,"") | C35: =IFERROR(SUMPRODUCT(IFERROR(--('W11'!$N$9:$N$109="G2")*'W11'!$H$9:$H$109*('W11'!$I$9:$I$109+'W11'!$J$9:$J$109),0))/SUMPRODUCT(IFERROR(--('W10'!$N$9:$N$109="G2")*'W10'!$H$9:$H$109*('W10'!$I$9:$I$109+'W10'!$J$9:$J$109),0))-1,"") | D35: =IFERROR(SUMPRODUCT(IFERROR(--('W11'!$N$9:$N$109="G3")*'W11'!$H$9:$H$109*('W11'!$I$9:$I$109+'W11'!$J$9:$J$109),0))/SUMPRODUCT(IFERROR(--('W10'!$N$9:$N$109="G3")*'W10'!$H$9:$H$109*('W10'!$I$9:$I$109+'W10'!$J$9:$J$109),0))-1,"") | E35: =IFERROR(SUMPRODUCT(IFERROR(--('W11'!$N$9:$N$109="G4")*'W11'!$H$9:$H$109*('W11'!$I$9:$I$109+'W11'!$J$9:$J$109),0))/SUMPRODUCT(IFERROR(--('W10'!$N$9:$N$109="G4")*'W10'!$H$9:$H$109*('W10'!$I$9:$I$109+'W10'!$J$9:$J$109),0))-1,"")
A36: 12 | B36: =IFERROR(SUMPRODUCT(IFERROR(--('W12'!$N$9:$N$109="G1")*'W12'!$H$9:$H$109*('W12'!$I$9:$I$109+'W12'!$J$9:$J$109),0))/SUMPRODUCT(IFERROR(--('W11'!$N$9:$N$109="G1")*'W11'!$H$9:$H$109*('W11'!$I$9:$I$109+'W11'!$J$9:$J$109),0))-1,"") | C36: =IFERROR(SUMPRODUCT(IFERROR(--('W12'!$N$9:$N$109="G2")*'W12'!$H$9:$H$109*('W12'!$I$9:$I$109+'W12'!$J$9:$J$109),0))/SUMPRODUCT(IFERROR(--('W11'!$N$9:$N$109="G2")*'W11'!$H$9:$H$109*('W11'!$I$9:$I$109+'W11'!$J$9:$J$109),0))-1,"") | D36: =IFERROR(SUMPRODUCT(IFERROR(--('W12'!$N$9:$N$109="G3")*'W12'!$H$9:$H$109*('W12'!$I$9:$I$109+'W12'!$J$9:$J$109),0))/SUMPRODUCT(IFERROR(--('W11'!$N$9:$N$109="G3")*'W11'!$H$9:$H$109*('W11'!$I$9:$I$109+'W11'!$J$9:$J$109),0))-1,"") | E36: =IFERROR(SUMPRODUCT(IFERROR(--('W12'!$N$9:$N$109="G4")*'W12'!$H$9:$H$109*('W12'!$I$9:$I$109+'W12'!$J$9:$J$109),0))/SUMPRODUCT(IFERROR(--('W11'!$N$9:$N$109="G4")*'W11'!$H$9:$H$109*('W11'!$I$9:$I$109+'W11'!$J$9:$J$109),0))-1,"")
A37: 13 | B37: =IFERROR(SUMPRODUCT(IFERROR(--('W13'!$N$9:$N$109="G1")*'W13'!$H$9:$H$109*('W13'!$I$9:$I$109+'W13'!$J$9:$J$109),0))/SUMPRODUCT(IFERROR(--('W12'!$N$9:$N$109="G1")*'W12'!$H$9:$H$109*('W12'!$I$9:$I$109+'W12'!$J$9:$J$109),0))-1,"") | C37: =IFERROR(SUMPRODUCT(IFERROR(--('W13'!$N$9:$N$109="G2")*'W13'!$H$9:$H$109*('W13'!$I$9:$I$109+'W13'!$J$9:$J$109),0))/SUMPRODUCT(IFERROR(--('W12'!$N$9:$N$109="G2")*'W12'!$H$9:$H$109*('W12'!$I$9:$I$109+'W12'!$J$9:$J$109),0))-1,"") | D37: =IFERROR(SUMPRODUCT(IFERROR(--('W13'!$N$9:$N$109="G3")*'W13'!$H$9:$H$109*('W13'!$I$9:$I$109+'W13'!$J$9:$J$109),0))/SUMPRODUCT(IFERROR(--('W12'!$N$9:$N$109="G3")*'W12'!$H$9:$H$109*('W12'!$I$9:$I$109+'W12'!$J$9:$J$109),0))-1,"") | E37: =IFERROR(SUMPRODUCT(IFERROR(--('W13'!$N$9:$N$109="G4")*'W13'!$H$9:$H$109*('W13'!$I$9:$I$109+'W13'!$J$9:$J$109),0))/SUMPRODUCT(IFERROR(--('W12'!$N$9:$N$109="G4")*'W12'!$H$9:$H$109*('W12'!$I$9:$I$109+'W12'!$J$9:$J$109),0))-1,"")
A38: 14 | B38: =IFERROR(SUMPRODUCT(IFERROR(--('W14'!$N$9:$N$109="G1")*'W14'!$H$9:$H$109*('W14'!$I$9:$I$109+'W14'!$J$9:$J$109),0))/SUMPRODUCT(IFERROR(--('W13'!$N$9:$N$109="G1")*'W13'!$H$9:$H$109*('W13'!$I$9:$I$109+'W13'!$J$9:$J$109),0))-1,"") | C38: =IFERROR(SUMPRODUCT(IFERROR(--('W14'!$N$9:$N$109="G2")*'W14'!$H$9:$H$109*('W14'!$I$9:$I$109+'W14'!$J$9:$J$109),0))/SUMPRODUCT(IFERROR(--('W13'!$N$9:$N$109="G2")*'W13'!$H$9:$H$109*('W13'!$I$9:$I$109+'W13'!$J$9:$J$109),0))-1,"") | D38: =IFERROR(SUMPRODUCT(IFERROR(--('W14'!$N$9:$N$109="G3")*'W14'!$H$9:$H$109*('W14'!$I$9:$I$109+'W14'!$J$9:$J$109),0))/SUMPRODUCT(IFERROR(--('W13'!$N$9:$N$109="G3")*'W13'!$H$9:$H$109*('W13'!$I$9:$I$109+'W13'!$J$9:$J$109),0))-1,"") | E38: =IFERROR(SUMPRODUCT(IFERROR(--('W14'!$N$9:$N$109="G4")*'W14'!$H$9:$H$109*('W14'!$I$9:$I$109+'W14'!$J$9:$J$109),0))/SUMPRODUCT(IFERROR(--('W13'!$N$9:$N$109="G4")*'W13'!$H$9:$H$109*('W13'!$I$9:$I$109+'W13'!$J$9:$J$109),0))-1,"")
A39: 15 | B39: =IFERROR(SUMPRODUCT(IFERROR(--('W15'!$N$9:$N$109="G1")*'W15'!$H$9:$H$109*('W15'!$I$9:$I$109+'W15'!$J$9:$J$109),0))/SUMPRODUCT(IFERROR(--('W14'!$N$9:$N$109="G1")*'W14'!$H$9:$H$109*('W14'!$I$9:$I$109+'W14'!$J$9:$J$109),0))-1,"") | C39: =IFERROR(SUMPRODUCT(IFERROR(--('W15'!$N$9:$N$109="G2")*'W15'!$H$9:$H$109*('W15'!$I$9:$I$109+'W15'!$J$9:$J$109),0))/SUMPRODUCT(IFERROR(--('W14'!$N$9:$N$109="G2")*'W14'!$H$9:$H$109*('W14'!$I$9:$I$109+'W14'!$J$9:$J$109),0))-1,"") | D39: =IFERROR(SUMPRODUCT(IFERROR(--('W15'!$N$9:$N$109="G3")*'W15'!$H$9:$H$109*('W15'!$I$9:$I$109+'W15'!$J$9:$J$109),0))/SUMPRODUCT(IFERROR(--('W14'!$N$9:$N$109="G3")*'W14'!$H$9:$H$109*('W14'!$I$9:$I$109+'W14'!$J$9:$J$109),0))-1,"") | E39: =IFERROR(SUMPRODUCT(IFERROR(--('W15'!$N$9:$N$109="G4")*'W15'!$H$9:$H$109*('W15'!$I$9:$I$109+'W15'!$J$9:$J$109),0))/SUMPRODUCT(IFERROR(--('W14'!$N$9:$N$109="G4")*'W14'!$H$9:$H$109*('W14'!$I$9:$I$109+'W14'!$J$9:$J$109),0))-1,"")
